Workbook

Sheet Kim_Kay
A1: URL | B1: Name | C1: PlaylistID | D1: Followers | E1: 2026-03-01 | F1: 2026-03-02 | G1: 46084 | H1: 46085 | I1: 2026-03-05 | J1: 2026-03-06 | K1: 2026-03-07 | L1: 2026-03-08 | M1: 2026-03-09 | N1: 2026-03-10 | O1: 2026-03-11 | P1: 2026-03-12 | Q1: 2026-03-13 | R1: 2026-03-14 | S1: 2026-03-15 | T1: 2026-03-16 | U1: 2026-03-17 | V1: 2026-03-18 | W1: 2026-03-19 | X1: 2026-03-20 | Y1: 2026-03-21 | Z1: 2026-03-22 | AA1: 2026-03-23 | AB1: 2026-03-24 | AC1: 2026-03-25 | AD1: 2026-03-26 | AE1: 2026-03-27 | AF1: 2026-03-28 | AG1: 2026-03-29 | AH1: 2026-03-30 | AI1: 2026-03-31 | AJ1: 2026-04-01 | AK1: 2026-04-02 | AL1: 2026-04-03 | AM1: 2026-04-04 | AN1: 46117 | AO1: 2026-04-06 | AP1: 2026-04-07 | AQ1: 2026-04-08 | AR1: 2026-04-09 | AS1: 2026-04-10 | AT1: 2026-04-11 | AU1: 2026-04-12 | AV1: 2026-04-13 | AW1: 2026-04-14 | AX1: 2026-04-15 | AY1: 2026-04-16 | AZ1: 2026-04-17 | BA1: 2026-04-18 | BB1: 2026-04-19 | BC1: 2026-04-20 | BD1: 2026-04-21 | BE1: 2026-04-22 | BF1: 2026-04-23 | BG1: 2026-04-25 | BH1: 2026-04-26 | BI1: 2026-04-28 | BJ1: 2026-04-29 | BK1: 2026-04-30 | BL1: 2026-05-01 | BM1: 2026-05-02 | BN1: 2026-05-03 | BO1: 2026-05-04 | BP1: 2026-05-05 | BQ1: 2026-05-06
A2: https://open.spotify.com/playlist/7b0g0LmwCbY3Lst0UwAocY | B2: EHRENLOSE REMIXES 2026 🔥 KRASSE BASS REMIXES ⚡️ TIKTOK HITS | C2: 7b0g0LmwCbY3Lst0UwAocY | D2: 2101 | E2: 17 | F2: 7 | G2: 9 | H2: 11 | I2: 26 | J2: 15 | K2: 12 | L2: 7 | M2: 12 | N2: 10 | O2: 21 | P2: 17 | Q2: 17 | R2: 18 | S2: 10 | T2: 14 | U2: 11 | V2: 7 | W2: 8 | X2: 9 | Y2: 13 | Z2: 2 | AA2: 4 | AB2: 10 | AC2: 4 | AD2: 9 | AE2: 4 | AF2: 10 | AG2: 12 | AH2: 5 | AI2: 10 | AJ2: 2 | AK2: 7 | AL2: 5 | AM2: 5 | AN2: 9 | AO2: 8 | AP2: 7 | AQ2: 10 | AR2: 6 | AS2: 8 | AT2: 4 | AU2: 10 | AV2: 7 | AW2: 6 | AX2: 7 | AY2: 10 | AZ2: 5 | BA2: 3 | BB2: 3 | BC2: 4 | BD2: 5 | BE2: 5 | BF2: 4 | BG2: 16 | BH2: 5 | BI2: 10 | BJ2: 5 | BK2: 3 | BL2: 3 | BM2: 6 | BN2: 3 | BO2: 4 | BP2: 2 | BQ2: 2
A3: https://open.spotify.com/playlist/3WK4yg5FJqE9rZqjFwIVcY | B3: GYM HOUSE 2026 💪 HOUSE MIX 🏋️ WORKOUT MOTIVATION | C3: 3WK4yg5FJqE9rZqjFwIVcY | D3: 609 | E3: 4 | F3: 4 | G3: 9 | H3: 7 | I3: 6 | J3: 7 | K3: 6 | L3: 2 | M3: 11 | N3: 6 | O3: 6 | P3: 4 | Q3: 2 | R3: 9 | S3: 2 | T3: 5 | U3: 5 | V3: 4 | W3: 6 | X3: 4 | Y3: 5 | Z3: 2 | AA3: 3 | AB3: 6 | AC3: 8 | AD3: 6 | AE3: 5 | AF3: 1 | AG3: 5 | AH3: 3 | AI3: 1 | AJ3: 5 | AK3: 6 | AL3: 12 | AM3: 8 | AN3: 2 | AO3: 2 | AP3: 5 | AQ3: 9 | AR3: 4 | AS3: 11 | AT3: 8 | AU3: 6 | AV3: 5 | AW3: 8 | AX3: 3 | AY3: 8 | AZ3: 5 | BA3: 3 | BB3: 2 | BC3: 4 | BD3: 7 | BE3: 3 | BF3: 4 | BG3: 9 | BH3: 1 | BI3: 5 | BJ3: 4 | BK3: 6 | BL3: 8 | BM3: 6 | BN3: 2 | BO3: 4 | BP3: 5 | BQ3: 3
A4: https://open.spotify.com/playlist/4PppwTQL5IEin89PGgrRa8 | B4: JUMP ROPE 150 BPM 2026 ⏱️ CARDIO BEATS 🔥 WORKOUT HITS | C4: 4PppwTQL5IEin89PGgrRa8 | D4: 379 | E4: 5 | F4: 4 | G4: 3 | H4: 5 | I4: 1 | J4: 5 | K4: 5 | L4: 4 | M4: 5 | N4: 3 | O4: 2 | P4: 3 | Q4: 3 | R4: 0 | S4: 1 | T4: 3 | U4: 2 | V4: 2 | W4: 3 | X4: 6 | Y4: 2 | Z4: 5 | AA4: 0 | AB4: 3 | AC4: 2 | AD4: 4 | AE4: 0 | AF4: 3 | AG4: 4 | AH4: 2 | AI4: 2 | AJ4: 4 | AK4: 3 | AL4: 0 | AM4: 2 | AN4: 2 | AO4: 2 | AP4: 5 | AQ4: 5 | AR4: 3 | AS4: 1 | AT4: 3 | AU4: 4 | AV4: 3 | AW4: -1 | AX4: 3 | AY4: 5 | AZ4: 0 | BA4: 2 | BB4: 6 | BC4: 2 | BD4: 1 | BE4: 1 | BF4: 4 | BG4: 3 | BH4: 4 | BI4: 8 | BJ4: 3 | BK4: 5 | BL4: 5 | BM4: 5 | BN4: 1 | BO4: 1 | BP4: 5 | BQ4: 1
A5: https://open.spotify.com/playlist/3ujniTOeTw389Pr0yqAMfc | B5: YOGA INSTRUMENTAL MUSIC 2026 🌸 CHILL VIBES 🌿 RELAXING FLOW | C5: 3ujniTOeTw389Pr0yqAMfc | D5: 323 | E5: 2 | F5: -1 | G5: 4 | H5: 3 | I5: 1 | J5: 2 | K5: 0 | L5: 1 | M5: 4 | N5: 3 | O5: 3 | P5: 7 | Q5: 4 | R5: 3 | S5: 0 | T5: 5 | U5: 3 | V5: 9 | W5: 9 | X5: 4 | Y5: 5 | Z5: -1 | AA5: 4 | AB5: 3 | AC5: 6 | AD5: 2 | AE5: 3 | AF5: 2 | AG5: 3 | AH5: 1 | AI5: 0 | AJ5: 6 | AK5: 3 | AL5: 0 | AM5: 0 | AN5: 2 | AO5: 2 | AP5: 1 | AQ5: 1 | AR5: 2 | AS5: 2 | AT5: 2 | AU5: 0 | AV5: 4 | AW5: 2 | AX5: 2 | AY5: 1 | AZ5: 2 | BA5: 1 | BB5: 1 | BC5: 0 | BD5: 2 | BE5: 2 | BF5: 3 | BG5: 6 | BH5: 0 | BI5: 5 | BJ5: 3 | BK5: 0 | BL5: 1 | BM5: 0 | BN5: 1 | BO5: 1 | BP5: 0 | BQ5: -1
A6: https://open.spotify.com/playlist/2As1rpvNBf5cwK9XlKBdxy | B6: ZEN BUDDHISM MEDITATION 2026 🧘‍♂️ INNER PEACE 🌿 CALM FOCUS | C6: 2As1rpvNBf5cwK9XlKBdxy | D6: 303 | E6: 0 | F6: 5 | G6: 0 | H6: 3 | I6: 2 | J6: 3 | K6: 3 | L6: 1 | M6: 1 | N6: 2 | O6: 2 | P6: 2 | Q6: 1 | R6: 2 | S6: 3 | T6: 1 | U6: -1 | V6: 2 | W6: 4 | X6: 3 | Y6: 4 | Z6: 1 | AA6: 1 | AB6: 3 | AC6: 1 | AD6: 2 | AE6: 2 | AF6: 3 | AG6: 0 | AH6: 2 | AI6: 6 | AJ6: 4 | AK6: 4 | AL6: 3 | AM6: 3 | AN6: 3 | AO6: 3 | AP6: 1 | AQ6: 2 | AR6: 2 | AS6: 0 | AT6: 0 | AU6: 2 | AV6: 1 | AW6: 1 | AX6: 2 | AY6: 2 | AZ6: 4 | BA6: 2 | BB6: 0 | BC6: 1 | BD6: 3 | BE6: 1 | BF6: 3 | BG6: 2 | BH6: 3 | BI6: 6 | BJ6: 2 | BK6: 1 | BL6: 1 | BM6: 3 | BN6: 0 | BO6: 0 | BP6: 1 | BQ6: 3
A7: https://open.spotify.com/playlist/6WA06xeA5UbI06o4QgtC7j | B7: LUXURY HOTEL LOUNGE 2026 ✨ CHILLOUT 🎶 ELEGANT VIBES | C7: 6WA06xeA5UbI06o4QgtC7j | D7: 311 | E7: 5 | F7: 1 | G7: -1 | H7: 3 | I7: 1 | J7: 0 | K7: 1 | L7: 2 | M7: 7 | N7: 6 | O7: 6 | P7: 9 | Q7: 4 | R7: 4 | S7: 4 | T7: 5 | U7: 1 | V7: 4 | W7: 2 | X7: 4 | Y7: 5 | Z7: 5 | AA7: 3 | AB7: 5 | AC7: 6 | AD7: 4 | AE7: 2 | AF7: 1 | AG7: 2 | AH7: 3 | AI7: 1 | AJ7: 3 | AK7: 2 | AL7: 3 | AM7: 3 | AN7: 1 | AO7: 1 | AP7: 0 | AQ7: 2 | AR7: 1 | AS7: 6 | AT7: 2 | AU7: 3 | AV7: 2 | AW7: 1 | AX7: 1 | AY7: 0 | AZ7: 1 | BA7: 0 | BB7: 0 | BC7: 2 | BD7: 1 | BE7: 3 | BF7: 1 | BG7: 3 | BH7: 3 | BI7: 3 | BJ7: 1 | BK7: 0 | BL7: 2 | BM7: -1 | BN7: 1 | BO7: 0 | BP7: 0 | BQ7: 2
A8: https://open.spotify.com/playlist/6YWX5ByctWFb2nsQaY6r3G | B8: ZUMBA BEATS 140-150 BPM 2026 💃 ZUMBA WORKOUT 🔥 FITNESS DANCE MIX | C8: 6YWX5ByctWFb2nsQaY6r3G | D8: 177 | E8: 2 | F8: 0 | G8: 1 | H8: -1 | I8: 0 | J8: 2 | K8: 1 | L8: 0 | M8: 0 | N8: 1 | O8: 2 | P8: 2 | Q8: 1 | R8: 0 | S8: 1 | T8: 3 | U8: 3 | V8: 0 | W8: 0 | X8: 0 | Y8: 0 | Z8: 0 | AA8: 0 | AB8: 0 | AC8: 1 | AD8: 1 | AE8: 2 | AF8: 1 | AG8: 0 | AH8: 1 | AI8: 1 | AJ8: 1 | AK8: 1 | AL8: 0 | AM8: 0 | AN8: 1 | AO8: 0 | AP8: 2 | AQ8: 1 | AR8: 0 | AS8: 1 | AT8: 1 | AU8: 1 | AV8: 1 | AW8: 0 | AX8: 2 | AY8: 0 | AZ8: 0 | BA8: 0 | BB8: 1 | BC8: 1 | BD8: 0 | BE8: 2 | BF8: 0 | BG8: 2 | BH8: 0 | BI8: 0 | BJ8: 1 | BK8: 1 | BL8: 1 | BM8: 0 | BN8: 0 | BO8: 0 | BP8: 0 | BQ8: 0
A9: https://open.spotify.com/playlist/46fOOGy5b5J4buNttN14VN | B9: TREADMILL GYM 2026 👟 RUNNING BEATS ⚡ SPINNING WORKOUT MUSIC | C9: 46fOOGy5b5J4buNttN14VN | D9: 186 | E9: 2 | F9: 2 | G9: 2 | H9: 0 | I9: 3 | J9: 0 | K9: 0 | L9: 1 | M9: 3 | N9: 2 | O9: 3 | P9: 0 | Q9: 0 | R9: 1 | S9: 0 | T9: 2 | U9: 0 | V9: 2 | W9: 5 | X9: 1 | Y9: 0 | Z9: 3 | AA9: 1 | AB9: 1 | AC9: 1 | AD9: 1 | AE9: 0 | AF9: 2 | AG9: 0 | AH9: 2 | AI9: 3 | AJ9: 0 | AK9: 3 | AL9: -1 | AM9: 1 | AN9: 1 | AO9: 0 | AP9: 0 | AQ9: 1 | AR9: 2 | AS9: 3 | AT9: 2 | AU9: 0 | AV9: 3 | AW9: 0 | AX9: 0 | AY9: 0 | AZ9: 0 | BA9: 0 | BB9: 0 | BC9: 2 | BD9: 1 | BE9: 1 | BF9: 0 | BG9: 0 | BH9: 1 | BI9: 1 | BJ9: 0 | BK9: 1 | BL9: 0 | BM9: 0 | BN9: 0 | BO9: 1 | BP9: 0 | BQ9: -1
A10: https://open.spotify.com/playlist/6FD9ynYoynGAV2ucH9nzbJ | B10: RAP LOVE SONGS 2026 💕 ROMANTIC HITS ❤️ HIP HOP BALLADS | C10: 6FD9ynYoynGAV2ucH9nzbJ | D10: 170 | E10: 1 | F10: 1 | G10: 4 | H10: 2 | I10: 0 | J10: 4 | K10: 0 | L10: 0 | M10: 2 | N10: 3 | O10: 2 | P10: 2 | Q10: 0 | R10: 0 | S10: 2 | T10: 1 | U10: 0 | V10: 1 | W10: -1 | X10: 0 | Y10: 0 | Z10: 0 | AA10: 1 | AB10: 1 | AC10: 1 | AD10: 3 | AE10: 0 | AF10: 2 | AG10: 1 | AH10: 1 | AI10: 2 | AJ10: -1 | AK10: 0 | AL10: 0 | AM10: 0 | AN10: 2 | AO10: 2 | AP10: 0 | AQ10: -1 | AR10: 0 | AS10: 1 | AT10: 0 | AU10: -1 | AV10: 1 | AW10: -1 | AX10: 1 | AY10: 0 | AZ10: 0 | BA10: -1 | BB10: 0 | BC10: 2 | BD10: 0 | BE10: 1 | BF10: 0 | BG10: 1 | BH10: 0 | BI10: 1 | BJ10: 1 | BK10: 1 | BL10: 1 | BM10: 1 | BN10: 0 | BO10: 1 | BP10: 0 | BQ10: 0
A11: https://open.spotify.com/playlist/3r2lhwSFsiOvfHpmFEwraD | B11: ASTRAL PROJECTION 2026 ✨ OUT OF BODY 🌌 BINAURAL BEATS | C11: 3r2lhwSFsiOvfHpmFEwraD | D11: 216 | E11: 2 | F11: 1 | G11: 2 | H11: 0 | I11: 2 | J11: 2 | K11: 4 | L11: 2 | M11: 1 | N11: 5 | O11: 0 | P11: 2 | Q11: 6 | R11: 1 | S11: 1 | T11: 3 | U11: 1 | V11: 1 | W11: 0 | X11: 1 | Y11: 3 | Z11: 1 | AA11: 2 | AB11: 2 | AC11: 1 | AD11: 2 | AE11: 0 | AF11: 1 | AG11: 1 | AH11: 1 | AI11: 1 | AJ11: 1 | AK11: 0 | AL11: 1 | AM11: 1 | AN11: 2 | AO11: 1 | AP11: 0 | AQ11: 1 | AR11: 1 | AS11: 2 | AT11: 3 | AU11: 2 | AV11: 1 | AW11: 4 | AX11: 0 | AY11: 1 | AZ11: 1 | BA11: 1 | BB11: 1 | BC11: 0 | BD11: 2 | BE11: 4 | BF11: 0 | BG11: 4 | BH11: 0 | BI11: 3 | BJ11: 3 | BK11: -2 | BL11: 3 | BM11: 1 | BN11: 3 | BO11: 1 | BP11: 1 | BQ11: 2
A12: https://open.spotify.com/playlist/4CHrIx3CG98P2wBbuGwZN3 | B12: CHANSONS POUR LES ENFANTS 2026 🇫🇷 🎵 TUNES AMUSANTES 🎵 FRENCH KIDS SONGS 2026 🇫🇷 | C12: 4CHrIx3CG98P2wBbuGwZN3 | D12: 179 | E12: 1 | F12: 2 | G12: 0 | H12: 1 | I12: 0 | J12: 0 | K12: 3 | L12: 3 | M12: 1 | N12: 1 | O12: 2 | P12: 4 | Q12: 0 | R12: 1 | S12: 1 | T12: 0 | U12: 3 | V12: 2 | W12: 1 | X12: 3 | Y12: 2 | Z12: 1 | AA12: 1 | AB12: 0 | AC12: 1 | AD12: 3 | AE12: 1 | AF12: 0 | AG12: 0 | AH12: 0 | AI12: 1 | AJ12: 0 | AK12: 2 | AL12: 0 | AM12: 1 | AN12: 1 | AO12: 0 | AP12: 1 | AQ12: 0 | AR12: 0 | AS12: 0 | AT12: 0 | AU12: 1 | AV12: 0 | AW12: 3 | AX12: 0 | AY12: 1 | AZ12: 1 | BA12: 1 | BB12: 1 | BC12: 0 | BD12: -1 | BE12: 1 | BF12: 0 | BG12: 0 | BH12: 0 | BI12: 0 | BJ12: 0 | BK12: 0 | BL12: 1 | BM12: 1 | BN12: 1 | BO12: 0 | BP12: 1 | BQ12: 1
A13: https://open.spotify.com/playlist/7yJioyPTyi1hxcQN6K861p | B13: WALGESÄNGE 2026 🌊 SANFTE KLÄNGE 🐋 MEERESRUHE | C13: 7yJioyPTyi1hxcQN6K861p | D13: 239 | E13: 0 | F13: 2 | G13: 3 | H13: 3 | I13: 1 | J13: 0 | K13: 1 | L13: 1 | M13: 0 | N13: -1 | O13: 2 | P13: 4 | Q13: 0 | R13: 3 | S13: 0 | T13: 0 | U13: 1 | V13: 0 | W13: 3 | X13: 2 | Y13: 3 | Z13: 4 | AA13: 3 | AB13: 2 | AC13: 1 | AD13: 4 | AE13: 4 | AF13: 1 | AG13: 3 | AH13: 1 | AI13: 1 | AJ13: 4 | AK13: 1 | AL13: 8 | AM13: 3 | AN13: 2 | AO13: 1 | AP13: 1 | AQ13: 4 | AR13: 2 | AS13: 4 | AT13: 1 | AU13: 3 | AV13: 2 | AW13: 6 | AX13: 4 | AY13: 5 | AZ13: -1 | BA13: 4 | BB13: 3 | BC13: 1 | BD13: 2 | BE13: 1 | BF13: 2 | BG13: 2 | BH13: 3 | BI13: 4 | BJ13: 1 | BK13: 2 | BL13: 3 | BM13: 4 | BN13: 2 | BO13: 2 | BP13: 0 | BQ13: -2
... A33: https://open.spotify.com/playlist/0XCBGebzJtWCVjWgBq3SYW | B33: BANHO RELAXANTE 2026 🛁 MÚSICA SUAVE 🌿 RELAX TOTAL | C33: 0XCBGebzJtWCVjWgBq3SYW | D33: 81 | E33: 1 | F33: 0 | G33: 0 | H33: 1 | I33: 1 | J33: 1 | K33: 1 | L33: 1 | M33: 1 | N33: 0 | O33: 1 | P33: 0 | Q33: 0 | R33: 0 | S33: 0 | T33: 1 | U33: 1 | V33: 0 | W33: 1 | X33: 3 | Y33: 2 | Z33: 2 | AA33: 1 | AB33: 2 | AC33: 2 | AD33: 1 | AE33: 1 | AF33: 2 | AG33: 0 | AH33: 2 | AI33: 2 | AJ33: 0 | AK33: 0 | AL33: 0 | AM33: 0 | AN33: 0 | AO33: 0 | AP33: 0 | AQ33: 2 | AR33: -1 | AS33: 1 | AT33: 1 | AU33: 2 | AV33: 3 | AW33: 0 | AX33: 0 | AY33: 0 | AZ33: 0 | BA33: 2 | BB33: 0 | BC33: 0 | BD33: 0 | BE33: 2 | BF33: 0 | BG33: 0 | BH33: 0 | BI33: 1 | BJ33: 0 | BK33: 0 | BL33: 0 | BM33: 0 | BN33: 0 | BO33: 0 | BP33: 0 | BQ33: 0
A34: https://open.spotify.com/playlist/3UUFb7YQTE4OVm6ZNPBpq4 | B34: AGGRESSIVE BASS DROPS 140-150 BPM 2026 🔊 EDM FESTIVAL BANGERS | C34: 3UUFb7YQTE4OVm6ZNPBpq4 | D34: 60 | E34: 0 | F34: 0 | G34: 0 | H34: 0 | I34: 1 | J34: 0 | K34: 0 | L34: 0 | M34: 1 | N34: 0 | O34: 0 | P34: 2 | Q34: 1 | R34: 1 | S34: 1 | T34: 0 | U34: 1 | V34: 0 | W34: 1 | X34: 1 | Y34: 2 | Z34: 2 | AA34: 0 | AB34: 1 | AC34: 0 | AD34: 2 | AE34: 0 | AF34: 0 | AG34: 1 | AH34: 0 | AI34: 0 | AJ34: 0 | AK34: 0 | AL34: -1 | AM34: 0 | AN34: 1 | AO34: 0 | AP34: 1 | AQ34: 1 | AR34: 1 | AS34: 0 | AU34: 1 | AV34: 1 | AW34: 0 | AX34: 1 | AY34: 0 | AZ34: 1 | BA34: 0 | BB34: 1 | BC34: 0 | BD34: 0 | BE34: 0 | BF34: 0 | BG34: 0 | BH34: 1 | BI34: 0 | BJ34: 0 | BK34: 1 | BL34: 0 | BM34: 0 | BN34: 0 | BO34: 1 | BP34: 0 | BQ34: 0
A35: https://open.spotify.com/playlist/6fhjox82LDujbjYiqJVq33 | B35: CAR ENGINE SOUNDS 2026 🚗 VROOM VROOM ⚡ HIGH-SPEED TRACKS | C35: 6fhjox82LDujbjYiqJVq33 | D35: 110 | E35: 0 | F35: 1 | G35: 2 | H35: 0 | I35: 0 | J35: 1 | K35: 2 | L35: 1 | M35: 0 | N35: 5 | O35: 1 | P35: 0 | Q35: 2 | R35: 1 | S35: 1 | T35: 1 | U35: 0 | V35: 1 | W35: 2 | X35: 4 | Y35: 1 | Z35: 2 | AA35: -1 | AB35: 3 | AC35: 1 | AD35: 2 | AE35: 1 | AF35: 4 | AG35: 0 | AH35: 0 | AI35: 0 | AJ35: 0 | AK35: 0 | AL35: 1 | AM35: 2 | AN35: 0 | AO35: 0 | AP35: 2 | AQ35: 0 | AR35: 2 | AS35: 0 | AT35: -1 | AU35: 5 | AV35: 1 | AW35: 1 | AX35: 3 | AY35: 0 | AZ35: 0 | BA35: 1 | BB35: 1 | BC35: 2 | BD35: 0 | BE35: 1 | BF35: 0 | BG35: 2 | BH35: 0 | BI35: 3 | BJ35: 1 | BK35: 0 | BL35: 1 | BM35: 1 | BN35: 1 | BO35: 0 | BP35: 1 | BQ35: 2
A36: https://open.spotify.com/playlist/2O6XeXNWLeX5l883AbWnsj | B36: COOL DOWN POST-WORKOUT Recovery & Relaxed Energy 🌙✨ | C36: 2O6XeXNWLeX5l883AbWnsj | D36: 32 | E36: 0 | F36: 0 | G36: 0 | H36: 0 | I36: 0 | J36: 1 | K36: 0 | L36: 1 | M36: 0 | N36: 1 | O36: 1 | P36: 2 | Q36: 1 | R36: 0 | S36: 0 | T36: 1 | U36: 1 | V36: 1 | W36: 0 | X36: 1 | Y36: 0 | Z36: 1 | AA36: -1 | AB36: 1 | AC36: 0 | AD36: 0 | AE36: 0 | AF36: 0 | AG36: 1 | AH36: 0 | AI36: 0 | AJ36: 0 | AK36: 0 | AL36: 0 | AM36: 0 | AN36: 0 | AO36: 0 | AP36: 0 | AQ36: 1 | AR36: 0 | AS36: 0 | AT36: 0 | AU36: 0 | AV36: 0 | AW36: 0 | AX36: 0 | AY36: 0 | AZ36: 0 | BA36: 0 | BB36: 0 | BC36: 0 | BD36: 0 | BE36: 0 | BF36: 0 | BG36: 2 | BH36: 0 | BI36: 0 | BJ36: 0 | BK36: 1 | BL36: 0 | BM36: 0 | BN36: 0 | BO36: 0 | BP36: 0 | BQ36: 0
A37: https://open.spotify.com/playlist/375Yy8vx7Gxy4HQyue0Nv7 | B37: DEEP SLEEP FREQUENCIES 9 CHAKRAS 🌙 ENERGY HEALING 🕉️ CALM REST | C37: 375Yy8vx7Gxy4HQyue0Nv7 | D37: 88 | E37: 0 | F37: 1 | G37: 0 | H37: 0 | I37: 1 | J37: 0 | K37: 3 | L37: 1 | M37: 3 | N37: 2 | O37: 2 | P37: 0 | Q37: 0 | R37: 1 | S37: 0 | T37: 0 | U37: 0 | V37: 1 | W37: 0 | X37: 0 | Y37: 3 | Z37: 2 | AA37: 1 | AB37: 1 | AC37: 0 | AD37: 2 | AE37: 0 | AF37: 1 | AG37: 0 | AH37: 1 | AI37: 1 | AJ37: 0 | AK37: 0 | AL37: 0 | AM37: 0 | AN37: 0 | AO37: 0 | AP37: 1 | AQ37: 0 | AR37: 1 | AS37: 1 | AT37: 0 | AU37: 1 | AV37: 0 | AW37: 1 | AX37: 1 | AY37: 0 | AZ37: 0 | BA37: 0 | BB37: 2 | BC37: 0 | BD37: 0 | BE37: 0 | BF37: 0 | BG37: 2 | BH37: 1 | BI37: 0 | BJ37: 0 | BK37: 0 | BL37: 0 | BM37: 0 | BN37: 0 | BO37: 1 | BP37: -1 | BQ37: 0
A38: https://open.spotify.com/playlist/6Fzx9aQahLqi9QC39Y50Gg | B38: PEACEFUL JAPANESE SLEEP MUSIC 😴 KOTO LULLABIES | SERENE VIBES | C38: 6Fzx9aQahLqi9QC39Y50Gg | D38: 97 | E38: 0 | F38: 1 | G38: 0 | H38: 0 | I38: 0 | J38: 2 | K38: 0 | L38: 2 | M38: 5 | N38: 1 | O38: 1 | P38: 1 | Q38: 2 | R38: 0 | S38: 1 | T38: 2 | U38: 1 | V38: 4 | W38: 0 | X38: 1 | Y38: -1 | Z38: 0 | AA38: 2 | AB38: 1 | AC38: 0 | AD38: 0 | AE38: 0 | AF38: 2 | AG38: 0 | AH38: 0 | AI38: 1 | AJ38: 1 | AK38: 3 | AL38: 1 | AM38: 0 | AN38: 2 | AO38: 2 | AP38: 0 | AQ38: 5 | AR38: 1 | AS38: 1 | AT38: 0 | AU38: 1 | AV38: 4 | AW38: 1 | AX38: 3 | AY38: 2 | AZ38: 1 | BA38: 0 | BB38: 0 | BC38: 0 | BD38: 0 | BE38: 0 | BF38: 1 | BG38: 0 | BH38: 1 | BI38: 5 | BJ38: 0 | BK38: 1 | BL38: 1 | BM38: 1 | BN38: 0 | BO38: 1 | BP38: 1 | BQ38: 1
A39: https://open.spotify.com/playlist/2sRfIPSTBLZoaa1IHwTCTm | B39: MÚSICA ÉPICA 2026 🐉 ORQUESTAL ⚔️ BATALLAS HEROICAS | C39: 2sRfIPSTBLZoaa1IHwTCTm | D39: 91 | E39: 1 | F39: 2 | G39: 0 | H39: 1 | I39: 0 | J39: 1 | K39: 1 | L39: 1 | M39: 0 | N39: 2 | O39: 3 | P39: 0 | Q39: 1 | R39: 2 | S39: 0 | T39: 1 | U39: 2 | V39: 0 | W39: 0 | X39: 0 | Y39: 0 | Z39: 0 | AA39: 2 | AB39: 2 | AC39: 1 | AD39: 1 | AE39: 0 | AF39: 2 | AG39: 0 | AH39: 1 | AI39: 3 | AJ39: 2 | AK39: 0 | AL39: 0 | AM39: 0 | AN39: 0 | AO39: 0 | AP39: 1 | AQ39: 1 | AR39: 1 | AS39: 3 | AT39: 1 | AU39: 2 | AV39: 1 | AW39: 0 | AX39: 0 | AY39: 2 | AZ39: 0 | BA39: 0 | BB39: 0 | BC39: 1 | BD39: -1 | BE39: 0 | BF39: 2 | BG39: 1 | BH39: 1 | BI39: 3 | BJ39: 1 | BK39: -1 | BL39: 0 | BM39: 1 | BN39: 1 | BO39: 0 | BP39: 2 | BQ39: 3
A40: https://open.spotify.com/playlist/0Af9A0s9Cfi8jeJsEYdOuN | B40: ANGELIC Cover Songs ✨ | Soft Versions of Popular Hits | C40: 0Af9A0s9Cfi8jeJsEYdOuN | D40: 31 | E40: 0 | F40: 0 | G40: -1 | H40: 0 | I40: 0 | J40: 0 | K40: 0 | L40: 0 | M40: -1 | N40: 1 | O40: 1 | P40: 1 | Q40: -1 | R40: 0 | S40: -1 | T40: 2 | U40: 1 | V40: 0 | W40: 0 | X40: 0 | Y40: 0 | Z40: 1 | AA40: 0 | AB40: 1 | AC40: 0 | AD40: 0 | AE40: 0 | AF40: 0 | AG40: 2 | AH40: 0 | AI40: 2 | AJ40: -1 | AK40: 0 | AL40: 0 | AM40: 1 | AN40: 0 | AO40: 0 | AP40: 0 | AQ40: 1 | AR40: 0 | AS40: 0 | AT40: 0 | AU40: 0 | AV40: 0 | AW40: 0 | AX40: 0 | AY40: 0 | AZ40: 0 | BA40: 1 | BB40: 0 | BC40: 0 | BD40: 0 | BE40: 0 | BF40: 0 | BG40: -1 | BH40: 0 | BI40: 0 | BJ40: 2 | BK40: 0 | BL40: 0 | BM40: -1 | BN40: 1 | BO40: 0 | BP40: 1 | BQ40: 0
A41: https://open.spotify.com/playlist/6EkHz6MaQcvobOBTq5q1j8 | B41: RESTAURANT MUSIC 2026 🍷 SOFT POP 🌟 RELAXING HITS | C41: 6EkHz6MaQcvobOBTq5q1j8 | D41: 116 | E41: 1 | F41: 0 | G41: 2 | H41: 2 | I41: 1 | J41: 2 | K41: 1 | L41: 1 | M41: 1 | N41: 2 | O41: 2 | P41: 2 | Q41: 2 | R41: 2 | S41: 2 | T41: 2 | U41: 1 | V41: 3 | W41: 0 | X41: 3 | Y41: 1 | Z41: 0 | AA41: 0 | AB41: 0 | AC41: 1 | AD41: 0 | AE41: 0 | AF41: 0 | AG41: 0 | AH41: 0 | AI41: 3 | AJ41: 1 | AK41: 0 | AL41: 3 | AM41: 2 | AN41: 2 | AO41: 2 | AP41: 0 | AQ41: 0 | AR41: 0 | AS41: 0 | AT41: 4 | AU41: 2 | AV41: 1 | AW41: 0 | AX41: 0 | AY41: 0 | AZ41: 2 | BA41: 0 | BB41: 2 | BC41: 0 | BD41: 0 | BE41: 1 | BF41: 0 | BG41: 2 | BH41: 0 | BI41: 1 | BJ41: 0 | BK41: 1 | BL41: 0 | BM41: 2 | BN41: 2 | BO41: 1 | BP41: 3 | BQ41: 0
A42: https://open.spotify.com/playlist/6MqJyxbdpiPz6zONBc1QhW | B42: SAD VIOLIN 2026 🎻 EMOTIONAL CLASSICS 🌙 CALM INSTRUMENTALS | C42: 6MqJyxbdpiPz6zONBc1QhW | D42: 79 | E42: 0 | F42: 0 | G42: 1 | H42: 0 | I42: 0 | J42: 0 | K42: 1 | L42: 1 | M42: 2 | N42: 0 | O42: 2 | P42: 0 | Q42: 1 | R42: 1 | S42: 1 | T42: 1 | U42: 1 | V42: 2 | W42: 0 | X42: 0 | Y42: 0 | Z42: 2 | AA42: 0 | AB42: 0 | AC42: 0 | AD42: 0 | AE42: 0 | AF42: 1 | AG42: 0 | AH42: 1 | AI42: 0 | AJ42: 0 | AK42: 0 | AL42: 1 | AM42: 0 | AN42: 1 | AO42: 0 | AP42: 0 | AQ42: 1 | AR42: 0 | AS42: 0 | AT42: 0 | AU42: 0 | AV42: 0 | AW42: 0 | AX42: 2 | AY42: 0 | AZ42: 0 | BA42: 1 | BB42: 0 | BC42: 0 | BD42: 0 | BE42: 0 | BF42: 0 | BG42: 0 | BH42: 0 | BI42: 3 | BJ42: 0 | BK42: 0 | BL42: 0 | BM42: 0 | BN42: 1 | BO42: 0 | BP42: 1 | BQ42: 0
A43: https://open.spotify.com/playlist/34i5Onp05GNMOLGKoGxbrl | B43: FREAKY Bedroom jams 🥵😈💦 Freaky Playlist • Naughty Music 😏👅💦 | C43: 34i5Onp05GNMOLGKoGxbrl | D43: 67 | E43: 0 | F43: 0 | G43: 0 | H43: 1 | I43: 0 | J43: 0 | K43: -1 | L43: 2 | M43: 3 | N43: 3 | O43: 2 | P43: 3 | Q43: 2 | R43: 0 | S43: 2 | T43: 3 | U43: 1 | V43: 3 | W43: 0 | X43: 1 | Y43: 6 | Z43: 0 | AA43: 1 | AB43: 1 | AC43: 2 | AD43: 3 | AE43: 1 | AF43: 0 | AG43: 0 | AH43: 0 | AI43: 0 | AJ43: 3 | AK43: 0 | AL43: 0 | AM43: 0 | AN43: 1 | AO43: 1 | AP43: 1 | AQ43: 1 | AR43: 0 | AS43: 0 | AT43: 0 | AU43: 1 | AV43: 0 | AW43: 0 | AX43: 0 | AY43: 0 | AZ43: 0 | BA43: 0 | BB43: 0 | BC43: 0 | BD43: -1 | BE43: 0 | BF43: 0 | BG43: -1 | BH43: 0 | BI43: 0 | BJ43: 0 | BK43: 0 | BL43: 0 | BM43: 0 | BN43: 0 | BO43: 0 | BP43: 0 | BQ43: 0
A44: https://open.spotify.com/playlist/6YunZqom1xq8Rid5g5HtCg | B44: BLAZING Viral Mashups 2026 🔥 – TikTok Trending Sounds & Remixes | C44: 6YunZqom1xq8Rid5g5HtCg | D44: 37 | E44: 1 | F44: 0 | G44: 0 | H44: 0 | I44: 1 | J44: 2 | K44: 0 | L44: 2 | M44: 0 | N44: 1 | O44: 1 | P44: 0 | Q44: 1 | R44: 1 | S44: 0 | T44: 2 | U44: 0 | V44: 1 | W44: 0 | X44: 0 | Y44: 0 | Z44: 0 | AA44: 0 | AB44: 3 | AC44: 1 | AD44: 1 | AE44: 0 | AF44: 0 | AN44: 0 | AO44: 0
A45: https://open.spotify.com/playlist/0uYnh6k5LrtwS1WYTmjwhb | B45: DYNAMIC TikTok Trending Mashups 2026 🔥 – Remix Edits & Party Energy | C45: 0uYnh6k5LrtwS1WYTmjwhb | D45: 17 | E45: 0 | F45: 0 | G45: 0 | H45: 0 | I45: 0 | J45: 1 | K45: 0 | L45: 2 | M45: 1 | N45: 0 | O45: 1 | P45: 1 | Q45: 0 | R45: 0 | S45: 0 | T45: 1 | U45: 1 | V45: 1 | W45: 1 | X45: 2 | Y45: 0 | Z45: 0 | AA45: 0 | AB45: 2 | AC45: 0 | AD45: 3 | AE45: 0 | AF45: 0 | AN45: 0 | AO45: 0
A46: https://open.spotify.com/playlist/1aJPXIpbzt9XeyulTir5n1 | B46: AMAZING Mashups 2026 🔥 – Viral Sounds & Edit Transitions | C46: 1aJPXIpbzt9XeyulTir5n1 | D46: 21 | E46: 0 | F46: 0 | G46: 0 | H46: 0 | I46: 0 | J46: 0 | K46: 0 | L46: 0 | M46: 0 | N46: 0 | O46: 0 | P46: 0 | Q46: 1 | R46: 1 | S46: 0 | T46: 0 | U46: 0 | V46: 0 | W46: 0 | X46: 0 | Y46: 0 | Z46: 0 | AA46: 0 | AB46: 0 | AC46: 0 | AD46: 1 | AE46: 0 | AF46: 1 | AG46: 1 | AH46: 1 | AI46: 0 | AJ46: 0 | AK46: 0 | AL46: 0 | AM46: 1 | AN46: 0 | AO46: 0 | AP46: 0 | AQ46: 0 | AR46: 0 | AS46: 0 | AT46: 0 | AU46: 0 | AV46: 0 | AW46: 0 | AX46: 0 | AY46: 1 | AZ46: 0 | BA46: 0 | BB46: 0 | BC46: 0 | BD46: 0 | BE46: 0 | BF46: 0 | BG46: 0 | BH46: 0 | BI46: 0 | BJ46: 0 | BK46: 0 | BL46: 0 | BM46: 0 | BN46: 0 | BO46: 0 | BP46: 0 | BQ46: 1
A47: https://open.spotify.com/playlist/2LJTmT4QWHntCkmi8jNjw3 | B47: EXPLOSIVE TikTok Mashup Party Mix 2026 🔥 – Hype Songs & Remix Drops | C47: 2LJTmT4QWHntCkmi8jNjw3 | D47: 49 | E47: 0 | F47: 1 | G47: 0 | H47: 1 | I47: 0 | J47: 1 | K47: 0 | L47: 1 | M47: 0 | N47: 1 | O47: 1 | P47: 1 | Q47: 3 | R47: 1 | S47: 0 | T47: 0 | U47: 0 | V47: 0 | W47: 1 | X47: 2 | Y47: 1 | Z47: 1 | AA47: 1 | AB47: 0 | AC47: 1 | AD47: 3 | AE47: 0 | AF47: 1 | AG47: 1 | AH47: 2 | AI47: 1 | AJ47: 1 | AK47: 1 | AL47: 3 | AM47: 0 | AN47: 1 | AO47: 1 | AP47: 2 | AQ47: 0 | AR47: 1 | AS47: 1 | AT47: 1 | AU47: 0 | AV47: 0 | AW47: 2 | AX47: 0 | AY47: 0 | AZ47: 1 | BA47: 0 | BB47: 0 | BC47: 0 | BD47: 0 | BE47: 0 | BF47: 0 | BG47: 0 | BH47: 0 | BI47: 0 | BJ47: 0 | BK47: 0 | BL47: 0 | BM47: 0 | BN47: 0 | BO47: 0 | BP47: 0 | BQ47: -1
A48: https://open.spotify.com/playlist/508IOoSYdvS0f9VtiDABsc | B48: UNSTOPPABLE Viral Mashups Nonstop 2026 🔥 – Trending Audio & FYP Mix | C48: 508IOoSYdvS0f9VtiDABsc | D48: 40 | E48: 0 | F48: 0 | G48: 0 | H48: 0 | I48: 1 | J48: 0 | K48: 0 | L48: 1 | M48: 0 | N48: 1 | O48: 0 | P48: 1 | Q48: 1 | R48: 3 | S48: 0 | T48: 0 | U48: 1 | V48: 0 | W48: 0 | X48: 0 | Y48: 0 | Z48: 1 | AA48: 1 | AB48: 0 | AC48: 0 | AD48: 1 | AE48: 1 | AF48: 1 | AG48: 1 | AH48: 0 | AI48: 0 | AJ48: 1 | AK48: 1 | AL48: 1 | AM48: 0 | AN48: 0 | AO48: 0 | AP48: 1 | AQ48: 0 | AR48: 0 | AS48: 1 | AT48: 1 | AU48: 0 | AV48: 0 | AW48: 0 | AX48: 0 | AY48: 0 | AZ48: 1 | BA48: 0 | BB48: 0 | BC48: 0 | BD48: 1 | BE48: 0 | BF48: 0 | BG48: 0 | BH48: 1 | BI48: 0 | BJ48: 0 | BK48: 0 | BL48: 0 | BM48: 0 | BN48: 0 | BO48: 0 | BP48: 0 | BQ48: 0
A49: https://open.spotify.com/playlist/1X7ATqiEK5rWexOsSHA6MX | B49: HYPER TikTok Mashups 2026 🔥 – Sped Up, Slow Reverb & Viral Edits | C49: 1X7ATqiEK5rWexOsSHA6MX | D49: 0 | E49: 0 | F49: 0 | G49: 0 | H49: 0 | I49: 0 | J49: 0 | K49: 0 | L49: 0 | M49: 0 | N49: 0 | O49: 0 | P49: 0 | Q49: 0 | R49: 0 | S49: 0 | T49: 0 | U49: 0 | V49: 0 | W49: 0 | X49: 0 | Y49: 0 | Z49: 0 | AA49: 0 | AB49: 0 | AC49: 0 | AD49: 0 | AE49: 0 | AF49: 0 | AN49: 0 | AO49: 0
A50: https://open.spotify.com/playlist/1qqbf8p7OpG2qndH31pXfb | B50: ICONIC Mashup Remix Hits 2026 🔥 – Viral Social Media Sounds | C50: 1qqbf8p7OpG2qndH31pXfb | D50: 60 | E50: 1 | F50: 1 | G50: 0 | H50: 0 | I50: 1 | J50: 0 | K50: 1 | L50: 1 | M50: 0 | N50: 0 | O50: 1 | P50: 3 | Q50: 0 | R50: 2 | S50: 1 | T50: 1 | U50: 1 | V50: 0 | W50: 2 | X50: 2 | Y50: 2 | Z50: 4 | AA50: 2 | AB50: 2 | AC50: 1 | AD50: 3 | AE50: 0 | AF50: 2 | AG50: 1 | AH50: 0 | AI50: 2 | AJ50: 3 | AK50: 1 | AL50: 1 | AM50: 0 | AN50: 1 | AO50: 0 | AP50: 1 | AQ50: 1 | AR50: 0 | AS50: 0 | AT50: 1 | AU50: 1 | AV50: 0 | AW50: 0 | AX50: 0 | AY50: 0 | AZ50: 3 | BA50: 0 | BB50: 0 | BC50: 2 | BD50: 1 | BE50: 0 | BF50: 1 | BG50: 0 | BH50: 1 | BI50: 0 | BJ50: 0 | BK50: 0 | BL50: 0 | BM50: 0 | BN50: -1 | BO50: 0 | BP50: 0 | BQ50: 0
A51: https://open.spotify.com/playlist/3wEu10XQfI1dDqzSCXqy6r | B51: INSANE Mashup Songs 2026 🔥 – Viral Audio, Remix Drops & Edit Mix | C51: 3wEu10XQfI1dDqzSCXqy6r | D51: 31 | E51: 0 | F51: 0 | G51: 0 | H51: 0 | I51: 2 | J51: 1 | K51: 1 | L51: 0 | M51: 0 | N51: 0 | O51: 0 | P51: 0 | Q51: 1 | R51: 2 | S51: 0 | T51: 1 | U51: 0 | V51: 0 | W51: 0 | X51: 1 | Y51: 1 | Z51: 0 | AA51: 1 | AB51: 0 | AC51: 0 | AD51: 0 | AE51: 0 | AF51: 0 | AG51: 0 | AH51: 1 | AI51: 0 | AJ51: 1 | AK51: 1 | AL51: 2 | AM51: 1 | AN51: 1 | AO51: 0 | AP51: 0 | AQ51: 3 | AR51: 2 | AS51: 2 | AT51: 0 | AU51: 0 | AV51: 0 | AW51: 0 | AX51: 2 | AY51: 1 | AZ51: 0 | BA51: 0 | BB51: 0 | BC51: 0 | BD51: 0 | BE51: 0 | BF51: 0 | BG51: 0 | BH51: 0 | BI51: 1 | BJ51: 0 | BK51: 0 | BL51: 0 | BM51: 0 | BN51: 0 | BO51: 0 | BP51: 0 | BQ51: 0
A52: https://open.spotify.com/playlist/2b6B54oIPdae1Y4gZyDmat | B52: LEGENDARY Mashup Songs 2026 🔥 – Viral Remix Compilation & Transitions | C52: 2b6B54oIPdae1Y4gZyDmat | D52: 28 | E52: 0 | F52: 1 | G52: 0 | H52: 1 | I52: 0 | J52: 0 | K52: 0 | L52: 1 | M52: 0 | N52: 1 | O52: 0 | P52: 0 | Q52: 0 | R52: 0 | S52: 0 | T52: 0 | U52: 3 | V52: 0 | W52: 0 | X52: 0 | Y52: 0 | Z52: 0 | AA52: 0 | AB52: 0 | AC52: 0 | AD52: 1 | AE52: 1 | AF52: 0 | AG52: 0 | AH52: 0 | AI52: 0 | AJ52: 2 | AK52: 0 | AL52: 0 | AM52: 0 | AN52: 0 | AO52: 0 | AP52: 0 | AQ52: 1 | AR52: 0 | AS52: 0 | AT52: 0 | AU52: 1 | AV52: 0 | AW52: 0 | AX52: 0 | AY52: 0 | AZ52: 0 | BA52: 1 | BB52: 0 | BC52: 0 | BD52: 0 | BE52: 0 | BF52: 0 | BG52: 0 | BH52: 0 | BI52: 0 | BJ52: 0 | BK52: 0 | BL52: 0 | BM52: 0 | BN52: 0 | BO52: 0 | BP52: 0 | BQ52: 0
A53: https://open.spotify.com/playlist/3qS2CNg2WJfG57au8L9jG4 | B53: MAIN CHARACTER Mashups 2026 🔥 – TikTok Trending Remixes | C53: 3qS2CNg2WJfG57au8L9jG4 | D53: 11 | E53: 0 | F53: 0 | G53: 0 | H53: 1 | I53: 0 | J53: 0 | K53: 0 | L53: 1 | M53: 2 | N53: 0 | O53: 0 | P53: 0 | Q53: 0 | R53: 2 | S53: 0 | T53: 0 | U53: 1 | V53: 0 | W53: 0 | X53: 0 | Y53: 0 | Z53: 2 | AA53: 0 | AB53: 1 | AC53: 0 | AD53: 0 | AE53: 0 | AF53: 0 | AN53: 0 | AO53: 0
A54: https://open.spotify.com/playlist/1ctd74It4kIuf9iCjzn4LB | B54: WILD TikTok Mashups 2026 🔥 – Sped Up, Slow Reverb & Viral Edits | C54: 1ctd74It4kIuf9iCjzn4LB | D54: 30 | E54: 1 | F54: 0 | G54: 0 | H54: 0 | I54: 0 | J54: 0 | K54: 0 | L54: 1 | M54: 1 | N54: 1 | O54: 0 | P54: 1 | Q54: 0 | R54: 0 | S54: 2 | T54: 1 | U54: 2 | V54: 1 | W54: 0 | X54: 1 | Y54: 1 | Z54: 0 | AA54: 0 | AB54: 1 | AC54: 1 | AD54: 1 | AE54: 0 | AF54: 0 | AG54: 1 | AH54: 1 | AI54: 0 | AJ54: 0 | AK54: 0 | AL54: 0 | AM54: 0 | AN54: 0 | AO54: 0 | AP54: 0 | AQ54: 0 | AR54: 1 | AS54: 0 | AT54: 1 | AU54: 0 | AV54: 1 | AW54: 0 | AX54: 0 | AY54: 1 | AZ54: 0 | BA54: 0 | BB54: 0 | BC54: 0 | BD54: 1 | BE54: 0 | BF54: 0 | BG54: 0 | BH54: 0 | BI54: 0 | BJ54: -1 | BK54: 0 | BL54: 0 | BM54: 0 | BN54: 0 | BO54: 0 | BP54: 0 | BQ54: 0
A55: https://open.spotify.com/playlist/3C9xPNfyRXt66BV4r8tNNM | B55: GOATED Viral Mashups 2026 🔥 – FYP Remix & Trending Sounds | C55: 3C9xPNfyRXt66BV4r8tNNM | D55: 21 | E55: 1 | F55: 0 | G55: 0 | H55: 0 | I55: 0 | J55: 1 | K55: 1 | L55: 1 | M55: 0 | N55: 0 | O55: 0 | P55: 0 | Q55: 0 | R55: 0 | S55: 0 | T55: 0 | U55: 1 | V55: 0 | W55: 0 | X55: 0 | Y55: 0 | Z55: 0 | AA55: 1 | AB55: 2 | AC55: 0 | AD55: 1 | AE55: 0 | AF55: 1 | AG55: 1 | AH55: 0 | AI55: 1 | AJ55: 1 | AK55: 1 | AL55: 0 | AM55: 0 | AN55: 1 | AO55: 0 | AP55: 0 | AQ55: 0 | AR55: 0 | AS55: 2 | AT55: 0 | AU55: 0 | AV55: 0 | AW55: 0 | AX55: 0 | AY55: 0 | AZ55: 0 | BA55: 0 | BB55: 0 | BC55: 0 | BD55: 1 | BE55: 0 | BF55: 0 | BG55: 0 | BH55: 1 | BI55: 0 | BJ55: -1 | BK55: 0 | BL55: 0 | BM55: 0 | BN55: 0 | BO55: 0 | BP55: 0 | BQ55: 0
A56: https://open.spotify.com/playlist/0Gfr4xoaOvaDWPH9Gxp1s0 | B56: WILD TikTok Viral Mashups 2026 🔥 – Trending Sounds & Hype Remixes | C56: 0Gfr4xoaOvaDWPH9Gxp1s0 | D56: 10 | E56: 0 | F56: 0 | G56: 0 | H56: 0 | I56: 0 | J56: 0 | K56: 0 | L56: 0 | M56: 0 | N56: 0 | O56: 0 | P56: 0 | Q56: 1 | R56: 1 | S56: 1 | T56: 1 | U56: 0 | V56: 1 | W56: 0 | X56: 0 | Y56: -1 | Z56: 1 | AA56: 0 | AB56: 0 | AC56: 0 | AD56: 1 | AE56: 0 | AF56: 1 | AN56: 0 | AO56: 0
A57: https://open.spotify.com/playlist/7v5DJrB9p2BYdrlPDClEiu | B57: NEXT LEVEL Viral Mashups 2026 🔥 – FYP Remix & Trending Sounds | C57: 7v5DJrB9p2BYdrlPDClEiu | D57: 7 | E57: 0 | F57: 0 | G57: 0 | H57: 0 | I57: 0 | J57: 0 | K57: 0 | L57: 1 | M57: 0 | N57: 1 | O57: 0 | P57: 0 | Q57: 1 | R57: 0 | S57: 2 | T57: 0 | U57: 0 | V57: 0 | W57: 0 | X57: 0 | Y57: 0 | Z57: 0 | AA57: 0 | AB57: 0 | AC57: 0 | AD57: 0 | AE57: 1 | AF57: 0 | AN57: 0 | AO57: 0
A58: https://open.spotify.com/playlist/4cshCFrDinD0sVSbXfUE1T | B58: UNREAL Mashup Songs 2026 🔥 – Viral Audio, Remix Drops & Edit Mix | C58: 4cshCFrDinD0sVSbXfUE1T | D58: 20 | E58: 0 | F58: 0 | G58: 1 | H58: 2 | I58: 1 | J58: 0 | K58: 0 | L58: 0 | M58: 0 | N58: 2 | O58: 0 | P58: 2 | Q58: 0 | R58: -1 | S58: 0 | T58: 0 | U58: 0 | V58: 0 | W58: 3 | X58: 0 | Y58: 0 | Z58: 1 | AA58: 0 | AB58: 0 | AC58: 0 | AD58: 1 | AE58: 0 | AF58: 0 | AG58: 0 | AH58: 0 | AI58: 0 | AJ58: 0 | AK58: 0 | AL58: 0 | AM58: 0 | AN58: -1 | AO58: 0 | AP58: 0 | AQ58: 0 | AR58: 0 | AS58: 0 | AT58: 0 | AU58: 0 | AV58: 0 | AW58: -1 | AX58: 0 | AY58: 0 | AZ58: 0 | BA58: 0 | BB58: 0 | BC58: 0 | BD58: 0 | BE58: 0 | BF58: 0 | BG58: 0 | BH58: 0 | BI58: 0 | BJ58: 0 | BK58: 0 | BL58: 0 | BM58: 0 | BN58: 0 | BO58: 0 | BP58: 0 | BQ58: 0
A59: https://open.spotify.com/playlist/5qrZ7Z77UfIOUeY6m9xmBF | B59: OBSESSIVE TikTok Mashups 2026 🔥 – Trending Reels Audio | C59: 5qrZ7Z77UfIOUeY6m9xmBF | D59: 3 | E59: 0 | F59: 0 | G59: 0 | H59: 0 | I59: 0 | J59: 0 | K59: 0 | L59: 1 | M59: 0 | N59: 0 | O59: 0 | P59: 1 | Q59: 0 | R59: 0 | S59: 0 | T59: 1 | U59: 0 | V59: 0 | W59: 0 | X59: 0 | Y59: 0 | Z59: 0 | AA59: 0 | AB59: 0 | AC59: 0 | AD59: 0 | AE59: 0 | AF59: 0 | AN59: 0 | AO59: 0
...

Sheet Arthur_LeGrand
A1: URL | B1: Name | C1: PlaylistID | D1: c | E1: 2026-03-01 | F1: 2026-03-02 | G1: 2026-03-03 | H1: 2026-03-04 | I1: 2026-03-05 | J1: 2026-03-06 | K1: 2026-03-07 | L1: 2026-03-08 | M1: 2026-03-09 | N1: 2026-03-10 | O1: 2026-03-11 | P1: 2026-03-12 | Q1: 2026-03-13 | R1: 2026-03-14 | S1: 2026-03-15 | T1: 2026-03-16 | U1: 2026-03-17 | V1: 2026-03-18 | W1: 2026-03-19 | X1: 2026-03-20 | Y1: 2026-03-21 | Z1: 2026-03-22 | AA1: 2026-03-23 | AB1: 2026-03-24 | AC1: 2026-03-25 | AD1: 2026-03-26 | AE1: 2026-03-27 | AF1: 2026-03-28 | AG1: 2026-03-29 | AH1: 2026-03-30 | AI1: 2026-03-31 | AJ1: 2026-04-01 | AK1: 2026-04-02 | AL1: 2026-04-03 | AM1: 2026-04-04 | AN1: 46117 | AO1: 2026-04-06 | AP1: 2026-04-07 | AQ1: 2026-04-08 | AR1: 2026-04-09 | AS1: 2026-04-10 | AT1: 2026-04-11 | AU1: 2026-04-12 | AV1: 2026-04-13 | AW1: 2026-04-14 | AX1: 2026-04-15 | AY1: 2026-04-16 | AZ1: 2026-04-17 | BA1: 2026-04-18 | BB1: 2026-04-19 | BC1: 2026-04-20 | BD1: 2026-04-21 | BE1: 2026-04-22 | BF1: 2026-04-23 | BG1: 2026-04-25 | BH1: 2026-04-26 | BI1: 2026-04-28 | BJ1: 2026-04-29 | BK1: 2026-04-30 | BL1: 2026-05-01 | BM1: 2026-05-02 | BN1: 2026-05-03 | BO1: 2026-05-04 | BP1: 2026-05-05 | BQ1: 2026-05-06
A2: ="https://open.spotify.com/playlist/" & C2 | B2: Druid Meditation | Celtic Ambient, Forest Ritual Sounds 2026 💎🌿 | C2: 7kL6pZJjgroakclJmbLUDz | D2: 287 | E2: 10 | F2: 5 | G2: 4 | H2: 5 | I2: 3 | J2: 4 | K2: 2 | L2: 7 | M2: 5 | N2: 6 | O2: 7 | P2: 5 | Q2: 2 | R2: 6 | S2: 4 | T2: 9 | U2: 3 | V2: 5 | W2: 3 | X2: 0 | Y2: 2 | Z2: 2 | AA2: -1 | AB2: 1 | AC2: 2 | AD2: 6 | AE2: 2 | AF2: 3 | AG2: 3 | AH2: 3 | AI2: 5 | AJ2: 8 | AK2: 3 | AL2: 5 | AM2: 0 | AN2: 3 | AO2: 3 | AP2: 3 | AQ2: 3 | AR2: 2 | AS2: 2 | AT2: 2 | AU2: 5 | AV2: 5 | AW2: 1 | AX2: 1 | AY2: 1 | AZ2: 2 | BA2: 5 | BB2: 5 | BC2: 6 | BD2: 4 | BE2: 1 | BF2: 2 | BG2: 6 | BH2: 4 | BI2: 3 | BJ2: 3 | BK2: 2 | BL2: 0 | BM2: 2 | BN2: 2 | BO2: 3 | BP2: 1 | BQ2: 3
A3: ="https://open.spotify.com/playlist/" & C3 | B3: Running Music 200 BPM | Super Fast Songs for Running & Extreme Speed Workouts ⚡🏃‍♂️ | C3: 28eKAWVCjQEz7BvJ4jDwS9 | D3: 430 | E3: 7 | F3: 2 | G3: 4 | H3: 8 | I3: 7 | J3: 6 | K3: 4 | L3: 9 | M3: 8 | N3: 8 | O3: 8 | P3: 9 | Q3: 8 | R3: 9 | S3: 5 | T3: 6 | U3: 5 | V3: 10 | W3: 7 | X3: 3 | Y3: 8 | Z3: 12 | AA3: 1 | AB3: 11 | AC3: 3 | AD3: 11 | AE3: 2 | AF3: 5 | AG3: 8 | AH3: 3 | AI3: 10 | AJ3: 4 | AK3: 6 | AL3: 8 | AM3: 4 | AN3: 6 | AO3: 6 | AP3: 7 | AQ3: 8 | AR3: 4 | AS3: 2 | AT3: 7 | AU3: 9 | AV3: 2 | AW3: 3 | AX3: 7 | AY3: 7 | AZ3: 2 | BA3: 6 | BB3: 3 | BC3: 4 | BD3: 7 | BE3: 7 | BF3: 4 | BG3: 7 | BH3: 3 | BI3: 7 | BJ3: 3 | BK3: 6 | BL3: 1 | BM3: 2 | BN3: 3 | BO3: 3 | BP3: 6 | BQ3: 4
A4: ="https://open.spotify.com/playlist/" & C4 | B4: Trending Praise & Worship 2026 | Gospel Hits, Worship Songs, Christian Praise, Viral Worship 🙏 | C4: 0lnvvp78nfDwiVkHH2k9BT | D4: 306 | E4: 6 | F4: 5 | G4: 4 | H4: 3 | I4: 10 | J4: 6 | K4: 10 | L4: 13 | M4: 4 | N4: 7 | O4: 7 | P4: 9 | Q4: 5 | R4: 6 | S4: 10 | T4: 5 | U4: 3 | V4: 3 | W4: 4 | X4: 3 | Y4: 5 | Z4: 5 | AA4: 6 | AB4: 8 | AC4: 2 | AD4: 3 | AE4: 3 | AF4: 1 | AG4: 2 | AH4: 1 | AI4: 4 | AJ4: 2 | AK4: 1 | AL4: 3 | AM4: 5 | AN4: 4 | AO4: 4 | AP4: 5 | AQ4: 1 | AR4: 3 | AS4: 6 | AT4: 2 | AU4: 7 | AV4: -1 | AW4: 2 | AX4: 1 | AY4: 3 | AZ4: 2 | BA4: 5 | BB4: 4 | BC4: 2 | BD4: 3 | BE4: 1 | BF4: 3 | BG4: 0 | BH4: 2 | BI4: 2 | BJ4: 0 | BK4: 0 | BL4: 1 | BM4: 2 | BN4: 4 | BO4: 0 | BP4: 1 | BQ4: 2
A5: ="https://open.spotify.com/playlist/" & C5 | B5: Spinning Songs 150-160 BPM 2026 | Spinning Workout, Cycling Music & Spin Class 🚴‍♀️⚡ | C5: 2DRV17IO3eYHq7CthMrbcd | D5: 165 | E5: 5 | F5: -1 | G5: 2 | H5: 6 | I5: 7 | J5: 4 | K5: 3 | L5: 2 | M5: 6 | N5: 0 | O5: 5 | P5: 4 | Q5: -1 | R5: 2 | S5: 0 | T5: 2 | U5: 3 | V5: 3 | W5: 0 | X5: 2 | Y5: 3 | Z5: 3 | AA5: 2 | AB5: 3 | AC5: 2 | AD5: 1 | AE5: 3 | AF5: 1 | AG5: 1 | AH5: 1 | AI5: 0 | AJ5: 2 | AK5: 0 | AL5: 0 | AM5: 0 | AN5: 0 | AO5: 0 | AP5: 0 | AQ5: 2 | AR5: 2 | AS5: 1 | AT5: 1 | AU5: 2 | AV5: 1 | AW5: 3 | AX5: 1 | AY5: 1 | AZ5: 1 | BA5: 1 | BB5: 1 | BC5: 2 | BD5: 2 | BE5: 2 | BF5: -1 | BG5: 0 | BH5: 1 | BI5: 3 | BJ5: 0 | BK5: 1 | BL5: 0 | BM5: 0 | BN5: 0 | BO5: 2 | BP5: 0 | BQ5: 1
A6: ="https://open.spotify.com/playlist/" & C6 | B6: EDM Club Bangers 2026 | Party Anthems, House Hits & Gym House 🔥🕺 | C6: 3hg5OBVSyRBEUZxolAYNFl | D6: 286 | E6: 5 | F6: 2 | G6: 4 | H6: 4 | I6: 2 | J6: 3 | K6: 5 | L6: 11 | M6: 1 | N6: 4 | O6: 4 | P6: 1 | Q6: 3 | R6: 4 | S6: 4 | T6: 6 | U6: 2 | V6: 5 | W6: 4 | X6: 3 | Y6: 5 | Z6: 3 | AA6: 1 | AB6: 3 | AC6: 6 | AD6: 2 | AE6: 6 | AF6: 5 | AG6: 3 | AH6: 7 | AI6: 3 | AJ6: 5 | AK6: 2 | AL6: 4 | AM6: 2 | AN6: 5 | AO6: 5 | AP6: 7 | AQ6: 3 | AR6: 5 | AS6: 5 | AT6: 4 | AU6: 6 | AV6: 4 | AW6: 1 | AX6: 3 | AY6: 1 | AZ6: 1 | BA6: 2 | BB6: 4 | BC6: 2 | BD6: 2 | BE6: 1 | BF6: 2 | BG6: 10 | BH6: 11 | BI6: 6 | BJ6: 1 | BK6: 2 | BL6: 8 | BM6: 8 | BN6: 4 | BO6: 3 | BP6: 3 | BQ6: 7
A7: ="https://open.spotify.com/playlist/" & C7 | B7: MAXIMALES Lernen für Prüfungen 📚 | Fokus Musik | Study Playlist | Konzentrationsmusik | C7: 4u5lK8uunFg2G18eb87fcK | D7: 57 | E7: 4 | F7: 0 | G7: 1 | H7: 1 | I7: 4 | J7: 1 | K7: 0 | L7: 1 | M7: 0 | N7: 1 | O7: 0 | P7: 2 | Q7: 1 | R7: -1 | S7: 2 | T7: 2 | U7: 2 | V7: 1 | W7: 0 | X7: 2 | Y7: -1 | Z7: 0 | AA7: 0 | AB7: 1 | AC7: 3 | AD7: 4 | AE7: 0 | AF7: 0 | AG7: 1 | AH7: 1 | AI7: 0 | AJ7: 0 | AK7: 0 | AL7: 0 | AM7: 1 | AN7: 1 | AO7: 0 | AP7: 0 | AQ7: 1 | AR7: 0 | AS7: 0 | AT7: 0 | AU7: 1 | AV7: 1 | AW7: 1 | AX7: 0 | AY7: 1 | AZ7: 0 | BA7: 0 | BB7: 1 | BC7: -1 | BD7: 0 | BE7: 0 | BF7: 1 | BG7: 0 | BH7: 0 | BI7: 0 | BJ7: 0 | BK7: 1 | BL7: 0 | BM7: 0 | BN7: 0 | BO7: 0 | BP7: 0 | BQ7: 0
A8: ="https://open.spotify.com/playlist/" & C8 | B8: Canzoni da Palestra 2026 🔥 Migliori Brani per Allenamento e Motivazione | Musica per la Palestra 💃 | C8: 01ctcL3jlXrcv03hOw7IDA | D8: 194 | E8: 4 | F8: 1 | G8: 7 | H8: 6 | I8: 4 | J8: 6 | K8: 1 | L8: 4 | M8: 4 | N8: 2 | O8: 6 | P8: 0 | Q8: 5 | R8: 4 | S8: 1 | T8: 6 | U8: 1 | V8: 2 | W8: 0 | X8: 1 | Y8: 2 | Z8: 3 | AA8: 1 | AB8: 1 | AC8: 0 | AD8: 3 | AE8: 1 | AF8: 3 | AG8: 3 | AH8: 2 | AI8: 1 | AJ8: 2 | AK8: 1 | AL8: 2 | AM8: 1 | AN8: 1 | AO8: 1 | AP8: 2 | AQ8: 1 | AR8: 2 | AS8: 3 | AT8: 4 | AU8: 1 | AV8: 2 | AW8: 4 | AX8: 5 | AY8: 3 | AZ8: 1 | BA8: 5 | BB8: 2 | BC8: 4 | BD8: 3 | BE8: 4 | BF8: 2 | BG8: 3 | BH8: 0 | BI8: -1 | BJ8: 0 | BK8: 1 | BL8: 2 | BM8: 1 | BN8: 0 | BO8: 0 | BP8: 1 | BQ8: 1
A9: ="https://open.spotify.com/playlist/" & C9 | B9: Gymrat 2026 | Hardcore Workout Music, Gym Motivation & Beast Mode 💥🌌 | C9: 3iRWGxDEoxPCLs6CDuCaK6 | D9: 220 | E9: 4 | F9: 2 | G9: 2 | H9: 3 | I9: 3 | J9: 4 | K9: 3 | L9: 5 | M9: 6 | N9: 3 | O9: 5 | P9: 1 | Q9: 4 | R9: 0 | S9: 2 | T9: 7 | U9: 1 | V9: 2 | W9: 5 | X9: 3 | Y9: 6 | Z9: 2 | AA9: 5 | AB9: 4 | AC9: 0 | AD9: 4 | AE9: 6 | AF9: 5 | AG9: 2 | AH9: 3 | AI9: 1 | AJ9: 2 | AK9: 4 | AL9: 2 | AM9: 4 | AN9: 5 | AO9: 4 | AP9: 2 | AQ9: 0 | AR9: 0 | AS9: 5 | AT9: 3 | AU9: 0 | AV9: 6 | AW9: 2 | AX9: 3 | AY9: 1 | AZ9: 3 | BA9: 4 | BB9: 4 | BC9: 2 | BD9: 5 | BE9: 4 | BF9: 4 | BG9: 2 | BH9: 1 | BI9: 10 | BJ9: 1 | BK9: 3 | BL9: 4 | BM9: 1 | BN9: 1 | BO9: 3 | BP9: 2 | BQ9: 2
A10: ="https://open.spotify.com/playlist/" & C10 | B10: Músicas para Aula de Spinning 2026 | Treino de Bike Indoor, Pop & EDM Energético 🚴‍♂️🎶 | C10: 651v5G7oEwoHQds973GEmX | D10: 578 | E10: 4 | F10: 5 | G10: 6 | H10: 5 | I10: 14 | J10: 9 | K10: 7 | L10: 0 | M10: 6 | N10: 12 | O10: 8 | P10: 12 | Q10: 8 | R10: 8 | S10: 0 | T10: 4 | U10: 11 | V10: 16 | W10: 10 | X10: 11 | Y10: 13 | Z10: 8 | AA10: 4 | AB10: 14 | AC10: 8 | AD10: 14 | AE10: 8 | AF10: 4 | AG10: 7 | AH10: 5 | AI10: 6 | AJ10: 9 | AK10: 2 | AL10: 6 | AM10: 6 | AN10: 7 | AO10: 6 | AP10: 8 | AQ10: 8 | AR10: 6 | AS10: 7 | AT10: 9 | AU10: 4 | AV10: 8 | AW10: 11 | AX10: 15 | AY10: 6 | AZ10: 8 | BA10: 7 | BB10: 6 | BC10: 11 | BD10: 5 | BE10: 8 | BF10: 10 | BG10: 18 | BH10: 7 | BI10: 8 | BJ10: 4 | BK10: 7 | BL10: 6 | BM10: 5 | BN10: 2 | BO10: 10 | BP10: 4 | BQ10: 8
A11: ="https://open.spotify.com/playlist/" & C11 | B11: Deep Ambient Journeys 💥🧠 | Cinematic Atmospheres, Focus Music, Expansive Sound Design 2026 🌌 | C11: 3cfDxi2qYDBfufkbGDL0i8 | D11: 106 | E11: 4 | F11: 2 | G11: 2 | H11: 3 | I11: 2 | J11: 2 | K11: 0 | L11: 2 | M11: 4 | N11: 1 | O11: 3 | P11: 3 | Q11: 2 | R11: 2 | S11: 4 | T11: 2 | U11: 0 | V11: 1 | W11: 2 | X11: 0 | Y11: 1 | Z11: 3 | AA11: 1 | AB11: 0 | AC11: 1 | AD11: 0 | AE11: 1 | AF11: 0 | AG11: 1 | AH11: 1 | AI11: 0 | AJ11: 1 | AK11: 2 | AL11: 0 | AM11: 0 | AN11: 0 | AO11: 0 | AP11: 0 | AQ11: 0 | AR11: 0 | AS11: 1 | AT11: 3 | AU11: 0 | AV11: 1 | AW11: 1 | AX11: 0 | AY11: -1 | AZ11: 0 | BA11: 0 | BB11: 0 | BC11: -1 | BD11: 0 | BE11: 1 | BF11: 1 | BG11: 0 | BH11: 0 | BI11: 1 | BJ11: 0 | BK11: 0 | BL11: 0 | BM11: 0 | BN11: 1 | BO11: 0 | BP11: 1 | BQ11: 1
A12: ="https://open.spotify.com/playlist/" & C12 | B12: Hard Techno 2026 | Bangers Only, Rave Energy & Peak-Time Beats 🔥💃 | C12: 2wQFTwvqOxxKo9q5pn61wG | D12: 80 | E12: 3 | F12: 1 | G12: 3 | H12: 1 | I12: 0 | J12: 1 | K12: 2 | L12: 1 | M12: 0 | N12: 3 | O12: 1 | P12: 1 | Q12: 1 | R12: -1 | S12: 0 | T12: 2 | U12: 2 | V12: 3 | W12: 1 | X12: 0 | Y12: 0 | Z12: 1 | AA12: 0 | AB12: 3 | AC12: 1 | AD12: 0 | AE12: 1 | AF12: 2 | AG12: 1 | AH12: 1 | AI12: 0 | AJ12: 0 | AK12: 1 | AL12: 0 | AM12: 0 | AN12: 0 | AO12: 0 | AP12: 0 | AQ12: 1 | AR12: 1 | AS12: 0 | AT12: 1 | AU12: 0 | AV12: 0 | AW12: 0 | AX12: 0 | AY12: 0 | AZ12: 1 | BA12: 2 | BB12: 2 | BC12: 0 | BD12: 1 | BE12: 1 | BF12: 0 | BG12: 1 | BH12: 0 | BI12: 0 | BJ12: 0 | BK12: 3 | BL12: -1 | BM12: 0 | BN12: 1 | BO12: 1 | BP12: 0 | BQ12: 0
A13: ="https://open.spotify.com/playlist/" & C13 | B13: Upbeat Pop Songs 2026 | Feel-Good Pop Hits & Happy Music ☀️🎶 | C13: 3efTWk4Zs5y1BsvfcjNfd0 | D13: 150 | E13: 3 | F13: 0 | G13: 3 | H13: 3 | I13: 2 | J13: 2 | K13: 1 | L13: 1 | M13: 3 | N13: 0 | O13: 5 | P13: 2 | Q13: 2 | R13: 2 | S13: 1 | T13: 3 | U13: 3 | V13: 2 | W13: 3 | X13: 3 | Y13: 1 | Z13: 1 | AA13: 3 | AB13: 2 | AC13: 2 | AD13: 2 | AE13: 1 | AF13: 4 | AG13: 2 | AH13: 1 | AI13: 2 | AJ13: 3 | AK13: 0 | AL13: 1 | AM13: 0 | AN13: 2 | AO13: 2 | AP13: 2 | AQ13: 1 | AR13: 2 | AS13: 2 | AT13: 0 | AU13: 2 | AV13: 5 | AW13: 2 | AX13: 4 | AY13: 1 | AZ13: 2 | BA13: 0 | BB13: 0 | BC13: -1 | BD13: 0 | BE13: 2 | BF13: 2 | BG13: 3 | BH13: 2 | BI13: 6 | BJ13: 1 | BK13: 2 | BL13: 2 | BM13: 2 | BN13: 3 | BO13: 1 | BP13: 2 | BQ13: 2
... A60: ="https://open.spotify.com/playlist/" & C60 | B60: Shaolin Meditation | Zen Focus, Martial Arts Calm, Deep Inner Balance 2026 🧘‍♀️ | C60: 1YQJfnMgKGfZKZmFnJN8nK | D60: 109 | E60: 0 | F60: 0 | G60: 0 | H60: 0 | I60: 1 | J60: 1 | K60: 3 | L60: 2 | M60: 0 | N60: 4 | O60: 1 | P60: 4 | Q60: 3 | R60: 1 | S60: 5 | T60: 4 | U60: 1 | V60: 4 | W60: 2 | X60: 0 | Y60: 0 | Z60: 0 | AA60: 1 | AB60: 1 | AC60: 0 | AD60: 1 | AE60: 1 | AF60: 1 | AG60: 1 | AH60: 0 | AI60: 4 | AJ60: 0 | AK60: -1 | AL60: 1 | AM60: 2 | AN60: 2 | AO60: 1 | AP60: 3 | AQ60: 1 | AR60: 0 | AS60: -1 | AT60: 3 | AU60: -1 | AV60: 2 | AW60: 2 | AX60: 0 | AY60: 1 | AZ60: 4 | BA60: 1 | BB60: 3 | BC60: 4 | BD60: 0 | BE60: 0 | BF60: 1 | BG60: 2 | BH60: 2 | BI60: 7 | BJ60: 3 | BK60: 1 | BL60: 1 | BM60: 2 | BN60: 0 | BO60: 2 | BP60: 2 | BQ60: 1
A61: ="https://open.spotify.com/playlist/" & C61 | B61: Ritmo BRUTAL: Cadencia 160-165 | Correr con RITMO 💪 | Música para Correr | Acompasado | C61: 2fYlxq67gy9IzOBPurXCsh | D61: 10 | E61: 0 | F61: 0 | G61: 0 | AN61: 0 | AO61: 0
A62: ="https://open.spotify.com/playlist/" & C62 | B62: 8 Hours of Sleep Music | Deep Rest & Relaxation 2026 🎉😌 | C62: 5x0ObIoVtv3EPgJ3x7hAsO | D62: 54 | E62: 0 | F62: 1 | G62: 2 | H62: 1 | I62: 2 | J62: 2 | K62: 0 | L62: 1 | M62: 0 | N62: 1 | O62: 1 | P62: 2 | Q62: 1 | R62: 0 | S62: 0 | T62: 0 | U62: 3 | V62: 0 | W62: 1 | X62: 1 | Y62: 1 | Z62: 0 | AA62: 1 | AB62: 1 | AC62: 2 | AD62: 0 | AE62: 0 | AF62: 2 | AG62: 0 | AH62: 1 | AI62: 1 | AJ62: 0 | AK62: 0 | AL62: 0 | AM62: 1 | AN62: 1 | AO62: 0 | AP62: 0 | AQ62: 2 | AR62: 0 | AS62: 0 | AT62: 1 | AU62: 1 | AV62: 0 | AW62: 0 | AX62: 4 | AY62: 0 | AZ62: 0 | BA62: -1 | BB62: 1 | BC62: 0 | BD62: 0 | BE62: 1 | BF62: 1 | BG62: 1 | BH62: 0 | BI62: 0 | BJ62: 1 | BK62: 1 | BL62: 0 | BM62: 0 | BN62: 0 | BO62: 0 | BP62: 0 | BQ62: 0
A63: ="https://open.spotify.com/playlist/" & C63 | B63: INTENSE Cours de SPINNING 160 BPM 🔥 Playlist Spinning Indoor | Musique Cardio Énergique | C63: 59IMOdaJRK3hQa2jtHoUQt | D63: 64 | E63: 0 | F63: 0 | G63: 0 | H63: 0 | I63: 0 | J63: 0 | K63: 0 | L63: 0 | M63: 0 | N63: 1 | O63: 0 | P63: 2 | Q63: 0 | R63: 1 | S63: 3 | T63: 1 | U63: 1 | V63: 2 | W63: 2 | X63: 4 | Y63: 1 | Z63: 3 | AA63: 0 | AB63: 0 | AC63: 1 | AD63: 1 | AE63: 0 | AF63: 3 | AG63: 3 | AH63: 1 | AI63: 1 | AJ63: 3 | AK63: 1 | AL63: 0 | AM63: 1 | AN63: 1 | AO63: 1 | AP63: 1 | AQ63: 2 | AR63: 1 | AS63: 1 | AT63: 1 | AU63: 1 | AV63: 0 | AW63: 1 | AX63: 1 | AY63: 0 | AZ63: 1 | BA63: 0 | BB63: 3 | BC63: 1 | BD63: 1 | BE63: 0 | BF63: 1 | BG63: 1 | BH63: -1 | BI63: 0 | BJ63: 0 | BK63: 0 | BL63: 1 | BM63: 0 | BN63: 0 | BO63: 0 | BP63: 0 | BQ63: 0
A64: ="https://open.spotify.com/playlist/" & C64 | B64: INSANE Running 150–160 BPM 🔥 150–160 BPM Running Music | Tempo Run Playlist | Cardio Training Songs | C64: 1BnkEG5sBSK4qUNCXR9EU6 | D64: 165 | E64: 0 | F64: 2 | G64: 3 | H64: 3 | I64: 2 | J64: 4 | K64: 3 | L64: 1 | M64: 5 | N64: 0 | O64: 4 | P64: 2 | Q64: 1 | R64: 0 | S64: 1 | T64: 3 | U64: 1 | V64: 5 | W64: 2 | X64: 2 | Y64: 2 | Z64: 3 | AA64: 5 | AB64: 0 | AC64: 3 | AD64: 3 | AE64: 4 | AF64: 1 | AG64: 4 | AH64: 1 | AI64: 1 | AJ64: 0 | AK64: 2 | AL64: 2 | AM64: 3 | AN64: 3 | AO64: 3 | AP64: -1 | AQ64: 3 | AR64: 2 | AS64: 1 | AT64: 3 | AU64: 4 | AV64: 1 | AW64: 5 | AX64: 3 | AY64: 0 | AZ64: 3 | BA64: 6 | BB64: 4 | BC64: 7 | BD64: 3 | BE64: 2 | BF64: 1 | BG64: 3 | BH64: 2 | BI64: 3 | BJ64: 3 | BK64: 5 | BL64: 3 | BM64: 2 | BN64: 0 | BO64: 2 | BP64: 0 | BQ64: 3
A65: ="https://open.spotify.com/playlist/" & C65 | B65: KRÄFTIG Cycling Mix 150-160 BPM 🔥 Indoor Spinning Playlist | Energiegeladene Cardio Musik | C65: 3NbkCqtMk9SOFbfQcAZS2X | D65: 236 | E65: 0 | F65: 0 | G65: 1 | H65: 3 | I65: 2 | J65: 2 | K65: 0 | L65: 3 | M65: 3 | N65: 1 | O65: 2 | P65: 1 | Q65: 3 | R65: 2 | S65: 4 | T65: 6 | U65: 4 | V65: 8 | W65: 6 | X65: 3 | Y65: 2 | Z65: 4 | AA65: 2 | AB65: 4 | AC65: 4 | AD65: 7 | AE65: 4 | AF65: 2 | AG65: 2 | AH65: 3 | AI65: 4 | AJ65: 3 | AK65: 2 | AL65: 9 | AM65: 4 | AN65: 3 | AO65: 3 | AP65: 5 | AQ65: 1 | AR65: 1 | AS65: 6 | AT65: 4 | AU65: 3 | AV65: 8 | AW65: 7 | AX65: 4 | AY65: 5 | AZ65: 2 | BA65: 1 | BB65: 7 | BC65: 6 | BD65: 2 | BE65: 3 | BF65: 4 | BG65: 6 | BH65: 3 | BI65: 7 | BJ65: 3 | BK65: 6 | BL65: 5 | BM65: 1 | BN65: 3 | BO65: 2 | BP65: 4 | BQ65: 3
A66: ="https://open.spotify.com/playlist/" & C66 | B66: Pure Adrenaline 🏋️⚡ | Techno & Hard Techno, Rave Energy, Workout & Peak Focus 🔊 | C66: 139nsBLwLbCRItoTTBLDDF | D66: 41 | E66: 0 | F66: 0 | G66: 1 | H66: 0 | I66: 0 | J66: 2 | K66: 1 | L66: 2 | M66: 0 | N66: 1 | O66: 0 | P66: 1 | Q66: 0 | R66: 0 | S66: 1 | T66: 1 | U66: 1 | V66: 2 | W66: 1 | X66: 0 | Y66: 0 | Z66: 0 | AA66: 0 | AB66: 1 | AC66: 0 | AD66: 0 | AE66: 0 | AF66: 0 | AG66: 1 | AH66: 0 | AI66: 0 | AJ66: 1 | AK66: 1 | AL66: 1 | AM66: 1 | AN66: 1 | AO66: 0 | AP66: 0 | AQ66: 1 | AR66: 0 | AS66: 0 | AT66: 0 | AU66: 0 | AV66: 2 | AW66: 4 | AX66: 1 | AY66: 1 | AZ66: 0 | BA66: 0 | BB66: 0 | BC66: 0 | BD66: 0 | BE66: 0 | BF66: 0 | BG66: 0 | BH66: 0 | BI66: 2 | BJ66: 1 | BK66: 0 | BL66: 0 | BM66: 1 | BN66: 0 | BO66: 0 | BP66: 0 | BQ66: 0
A67: ="https://open.spotify.com/playlist/" & C67 | B67: KRACHTIG Hardlopen 150–160 BPM 🔥 Running Muziek 150–160 BPM | Tempo Cardio Run Playlist | C67: 0d5wo3ZmbnrDi83CSiiBa9 | D67: 349 | E67: 0 | F67: 0 | G67: 1 | H67: 2 | I67: 4 | J67: 5 | K67: 4 | L67: 8 | M67: 10 | N67: 14 | O67: 1 | P67: 12 | Q67: 6 | R67: 8 | S67: 5 | T67: 7 | U67: 5 | V67: 15 | W67: 0 | X67: 4 | Y67: 5 | Z67: 9 | AA67: 7 | AB67: 8 | AC67: 1 | AD67: 2 | AE67: 3 | AF67: 8 | AG67: 9 | AH67: 6 | AI67: 3 | AJ67: 2 | AK67: 7 | AL67: 4 | AM67: 2 | AN67: 5 | AO67: 5 | AP67: 9 | AQ67: 3 | AR67: 6 | AS67: 3 | AT67: 7 | AU67: 7 | AV67: 12 | AW67: 6 | AX67: 5 | AY67: 9 | AZ67: 6 | BA67: 3 | BB67: 9 | BC67: 8 | BD67: 5 | BE67: 1 | BF67: 4 | BG67: 8 | BH67: 1 | BI67: 6 | BJ67: 3 | BK67: 3 | BL67: 4 | BM67: 2 | BN67: 6 | BO67: 1 | BP67: 6 | BQ67: 4
A68: ="https://open.spotify.com/playlist/" & C68 | B68: BRUTAL Running 150–160 BPM 🔥 Música Running 150–160 BPM | Playlist Tempo Run | Cardio | C68: 4HQDclD6nbheMyk5bRP6Zf | D68: 428 | E68: 0 | F68: 2 | G68: 2 | H68: 7 | I68: 9 | J68: 5 | K68: 4 | L68: 5 | M68: 6 | N68: 11 | O68: 7 | P68: 9 | Q68: 3 | R68: 7 | S68: 7 | T68: 7 | U68: 11 | V68: 6 | W68: 6 | X68: 7 | Y68: 3 | Z68: 10 | AA68: 6 | AB68: 2 | AC68: 9 | AD68: 3 | AE68: 0 | AF68: 4 | AG68: 2 | AH68: 4 | AI68: 3 | AJ68: 6 | AK68: 9 | AL68: 1 | AM68: 10 | AN68: 5 | AO68: 4 | AP68: 10 | AQ68: 4 | AR68: 6 | AS68: 10 | AT68: 5 | AU68: 10 | AV68: 12 | AW68: 6 | AX68: 18 | AY68: 9 | AZ68: 8 | BA68: 9 | BB68: 9 | BC68: 10 | BD68: 7 | BE68: 7 | BF68: 6 | BG68: 10 | BH68: 10 | BI68: 14 | BJ68: 7 | BK68: 2 | BL68: 4 | BM68: 6 | BN68: 9 | BO68: 5 | BP68: 6 | BQ68: 5
A69: ="https://open.spotify.com/playlist/" & C69 | B69: ADRENALINICO Mix Ciclismo 2026 🔥 Playlist Spinning Indoor | Musica Cardio Energica | C69: 5JZkaSR2VOW0Dpi9i8I9ug | D69: 104 | E69: 0 | F69: 0 | G69: 2 | H69: 5 | I69: 2 | J69: 3 | K69: 0 | L69: 1 | M69: 0 | N69: 1 | O69: 4 | P69: 2 | Q69: 3 | R69: 2 | S69: 4 | T69: 1 | U69: 2 | V69: 1 | W69: -1 | X69: 2 | Y69: 2 | Z69: 2 | AA69: 1 | AB69: 1 | AC69: 1 | AD69: 2 | AE69: 2 | AF69: 2 | AG69: 3 | AH69: 1 | AI69: 2 | AJ69: 1 | AK69: 1 | AL69: 0 | AM69: 1 | AN69: 1 | AO69: 0 | AP69: 3 | AQ69: 1 | AR69: 2 | AS69: 2 | AT69: 3 | AU69: 1 | AV69: 3 | AW69: 3 | AX69: 0 | AY69: 1 | AZ69: 0 | BA69: 1 | BB69: 0 | BC69: 0 | BD69: 1 | BE69: 2 | BF69: 0 | BG69: 4 | BH69: 1 | BI69: 4 | BJ69: 2 | BK69: 4 | BL69: 3 | BM69: 0 | BN69: 1 | BO69: 1 | BP69: 1 | BQ69: 1
A70: ="https://open.spotify.com/playlist/" & C70 | B70: BRUTAL 160-170 BPM Ciclismo 2026 🔥 Playlist Spinning Indoor | Música Cardio Energética | C70: 7EZurUdpzoFuFOPBOA49HV | D70: 246 | E70: 0 | F70: 1 | G70: 0 | H70: 4 | I70: 1 | J70: 7 | K70: 2 | L70: 1 | M70: 2 | N70: 4 | O70: 6 | P70: 6 | Q70: 4 | R70: 2 | S70: 4 | T70: 3 | U70: 4 | V70: 4 | W70: 3 | X70: 7 | Y70: 2 | Z70: 4 | AA70: 4 | AB70: 3 | AC70: 2 | AD70: 2 | AE70: 2 | AF70: 5 | AG70: 4 | AH70: 3 | AI70: 4 | AJ70: 6 | AK70: 6 | AL70: 8 | AM70: 1 | AN70: 3 | AO70: 2 | AP70: 7 | AQ70: 6 | AR70: 6 | AS70: 1 | AT70: 4 | AU70: 3 | AV70: 1 | AW70: 2 | AX70: 4 | AY70: 2 | AZ70: 4 | BA70: 6 | BB70: 6 | BC70: 2 | BD70: 4 | BE70: 15 | BF70: 6 | BG70: 5 | BH70: 3 | BI70: 5 | BJ70: 1 | BK70: 7 | BL70: 5 | BM70: 4 | BN70: 5 | BO70: 3 | BP70: 1 | BQ70: 2
A71: ="https://open.spotify.com/playlist/" & C71 | B71: POTENTE 160–165 Corsa Ritmica 💪 | Musica per Correre 160 BPM | Playlist Tempo Run | Cardio | C71: 4tnTjbeH0WjkWTaTOAxpnY | D71: 64 | E71: 0 | F71: 1 | G71: 0 | H71: 0 | I71: 1 | J71: 3 | K71: 0 | L71: 1 | M71: 0 | N71: 1 | O71: 2 | P71: 1 | Q71: 1 | R71: 2 | S71: 1 | T71: 0 | U71: 1 | V71: 1 | W71: 4 | X71: 3 | Y71: 0 | Z71: 1 | AA71: 0 | AB71: 2 | AC71: 2 | AD71: 1 | AE71: 0 | AF71: 1 | AG71: 2 | AH71: 2 | AI71: 0 | AJ71: 0 | AK71: 0 | AL71: 2 | AM71: 2 | AN71: 1 | AO71: 0 | AP71: 2 | AQ71: 0 | AR71: 2 | AS71: 1 | AT71: 1 | AU71: 4 | AV71: 0 | AW71: 2 | AX71: 1 | AY71: 3 | AZ71: 0 | BA71: 1 | BB71: 1 | BC71: 0 | BD71: 1 | BE71: 3 | BF71: 2 | BG71: 0 | BH71: 0 | BI71: 0 | BJ71: 0 | BK71: 0 | BL71: 0 | BM71: 0 | BN71: 0 | BO71: 1 | BP71: 0 | BQ71: 0
A72: ="https://open.spotify.com/playlist/" & C72 | B72: PAZZESCA Corsa 180–190 BPM 🔥 Musica per Correre Veloce | Playlist Jogging | C72: 3v68aBUy2LBHIfngDuOaif | D72: 112 | E72: 0 | F72: 0 | G72: 0 | H72: 0 | I72: 0 | J72: 0 | K72: 0 | L72: 1 | M72: 1 | N72: 2 | O72: 3 | P72: 2 | Q72: 4 | R72: 3 | S72: 4 | T72: 1 | U72: 3 | V72: 1 | W72: 1 | X72: 2 | Y72: 0 | Z72: 4 | AA72: 3 | AB72: 1 | AC72: 1 | AD72: 2 | AE72: 0 | AF72: 2 | AG72: 3 | AH72: 1 | AI72: 2 | AJ72: 1 | AK72: 0 | AL72: 2 | AM72: 2 | AN72: 2 | AO72: 2 | AP72: 0 | AQ72: 2 | AR72: 1 | AS72: 4 | AT72: 3 | AU72: 3 | AV72: 0 | AW72: 4 | AX72: 1 | AY72: 1 | AZ72: 0 | BA72: 1 | BB72: 4 | BC72: 0 | BD72: 1 | BE72: 1 | BF72: 0 | BG72: 5 | BH72: 2 | BI72: 0 | BJ72: 0 | BK72: 1 | BL72: 3 | BM72: 3 | BN72: 9 | BO72: 1 | BP72: 4 | BQ72: 2
A73: ="https://open.spotify.com/playlist/" & C73 | B73: Deep Ambient Journeys 💥🧠 | Cinematic Atmospheres, Focus Music, Expansive Sound Design 2026 🌌 | C73: 4LTmF1u0JT8GgxVaPrVu2p | D73: 0 | E73: 0 | F73: 0 | G73: 0 | H73: 0 | I73: 0 | J73: 0 | K73: 0 | L73: 0 | M73: 0 | N73: 0 | O73: 0 | P73: 0 | Q73: 0 | R73: 0 | S73: 0 | T73: 0 | U73: 0 | V73: 0 | W73: 0 | X73: 0 | Y73: 0 | Z73: 0 | AA73: 0 | AB73: 0 | AC73: 0 | AD73: 0 | AE73: 0 | AF73: 0 | AG73: 0 | AH73: 0 | AI73: 0 | AJ73: 0 | AK73: 0 | AL73: 0 | AM73: 0 | AN73: 0 | AO73: 0 | AP73: 0 | AQ73: 0 | AR73: 0 | AS73: 0 | AU73: 0 | AV73: 0 | AW73: 0 | AX73: 0 | AY73: 0 | AZ73: 0 | BA73: 0 | BB73: 0 | BC73: 0 | BD73: 0 | BE73: 0 | BF73: 0 | BG73: 0 | BH73: 0 | BI73: 0 | BJ73: 0 | BK73: 0 | BL73: 0 | BM73: 0 | BN73: 0 | BO73: 0 | BP73: 0 | BQ73: 0
A74: ="https://open.spotify.com/playlist/" & C74 | B74: Rowing Machine Songs 2026 | Rowing Workout Music, Cardio & Power Training 🎶💪 | C74: 3IdMMEysbfQ3IUD9a1pwJJ | D74: 135 | E74: 0 | F74: 3 | G74: 5 | H74: 1 | I74: 1 | J74: 0 | K74: 1 | L74: 0 | M74: 3 | N74: 0 | O74: 1 | P74: 0 | Q74: 0 | R74: 0 | S74: 2 | T74: 3 | U74: 3 | V74: 3 | W74: 3 | X74: 2 | Y74: 3 | Z74: 3 | AA74: 1 | AB74: 4 | AC74: 1 | AD74: 0 | AE74: 0 | AF74: 1 | AG74: 4 | AH74: 2 | AI74: 2 | AJ74: 1 | AK74: 1 | AL74: 3 | AM74: 1 | AN74: 2 | AO74: 1 | AP74: 1 | AQ74: 2 | AR74: 1 | AS74: 5 | AT74: 1 | AU74: 2 | AV74: 3 | AW74: 0 | AX74: 0 | AY74: 1 | AZ74: 3 | BA74: 3 | BB74: 6 | BC74: 3 | BD74: 1 | BE74: -1 | BF74: 2 | BG74: -1 | BH74: 2 | BI74: 2 | BJ74: 4 | BK74: 3 | BL74: 0 | BM74: 1 | BN74: 0 | BO74: 3 | BP74: 0 | BQ74: 3
A75: ="https://open.spotify.com/playlist/" & C75 | B75: Dance Night 2026 | Club Hits, Party Music & Nightlife Vibes 💃🔥 | C75: 5h15OO7PHSni0heAU44Gq1 | D75: 55 | E75: 0 | F75: 2 | G75: 3 | H75: 0 | I75: 0 | J75: 3 | K75: 2 | L75: 0 | M75: 1 | N75: 1 | O75: 0 | P75: 0 | Q75: 0 | R75: 1 | S75: 3 | T75: 1 | U75: 2 | V75: 2 | W75: 0 | X75: 0 | Y75: 0 | Z75: 0 | AA75: 0 | AB75: 0 | AC75: 1 | AD75: 3 | AE75: 0 | AF75: 1 | AG75: 0 | AH75: 0 | AI75: 0 | AJ75: 0 | AK75: 1 | AL75: 0 | AM75: 1 | AN75: 0 | AO75: 0 | AP75: -1 | AQ75: 0 | AR75: 0 | AS75: 0 | AT75: 0 | AU75: 0 | AV75: 1 | AW75: 0 | AX75: 0 | AY75: 0 | AZ75: 0 | BA75: 1 | BB75: 1 | BC75: 0 | BD75: 0 | BE75: 1 | BF75: 0 | BG75: 0 | BH75: 1 | BI75: 1 | BJ75: 0 | BK75: 0 | BL75: 0 | BM75: 1 | BN75: 0 | BO75: 0 | BP75: 0 | BQ75: 0
A76: ="https://open.spotify.com/playlist/" & C76 | B76: Beatport Top 100 | Tech House Charts, Club Anthems, Underground DJ Hits 2026 🎧🔥 | C76: 3CbvuaGKRkZ5QfKLmaPIaZ | D76: 67 | E76: 0 | F76: 0 | G76: 2 | H76: 2 | I76: -1 | J76: 2 | K76: 0 | L76: 1 | M76: 1 | N76: 3 | O76: 2 | P76: 2 | Q76: 2 | R76: 0 | S76: 0 | T76: 0 | U76: 1 | V76: 2 | W76: 2 | X76: 1 | Y76: 0 | Z76: 0 | AA76: 3 | AB76: 0 | AC76: 0 | AD76: 1 | AE76: 2 | AF76: 1 | AG76: 0 | AH76: 0 | AI76: 1 | AJ76: 0 | AK76: 1 | AL76: 0 | AM76: 0 | AN76: 0 | AO76: 0 | AP76: 2 | AQ76: 0 | AR76: 0 | AS76: 1 | AT76: 1 | AU76: 0 | AV76: 0 | AW76: 0 | AX76: 0 | AY76: 0 | AZ76: 2 | BA76: 1 | BB76: 3 | BC76: 0 | BD76: 0 | BE76: 0 | BF76: 0 | BG76: 0 | BH76: 1 | BI76: 1 | BJ76: 1 | BK76: 0 | BL76: 1 | BM76: 0 | BN76: 0 | BO76: 1 | BP76: 0 | BQ76: 2
A77: ="https://open.spotify.com/playlist/" & C77 | B77: Techno Summer Ibiza | Ibiza Techno, Beach Raves, Sunset Club Anthems 2026 ☀️🏝️ | C77: 4JgsrkH6NwiSDveDldF359 | D77: 46 | E77: 0 | F77: 0 | G77: 1 | H77: 2 | I77: 0 | J77: 2 | K77: 1 | L77: 1 | M77: 0 | N77: 0 | O77: 0 | P77: 1 | Q77: 1 | R77: 1 | S77: 0 | T77: 3 | U77: 0 | V77: 1 | W77: 1 | X77: 1 | Y77: 0 | Z77: 2 | AA77: -1 | AB77: 2 | AC77: 2 | AD77: 1 | AE77: 0 | AF77: 0 | AG77: 0 | AH77: 1 | AI77: -1 | AJ77: 0 | AK77: 0 | AL77: 0 | AM77: 0 | AN77: 0 | AO77: 0 | AP77: 0 | AQ77: 0 | AR77: 0 | AS77: 0 | AT77: 1 | AU77: 2 | AV77: 0 | AW77: 1 | AX77: 0 | AY77: 1 | AZ77: 0 | BA77: 0 | BB77: 1 | BC77: 0 | BD77: 0 | BE77: 0 | BF77: 0 | BG77: 1 | BH77: 1 | BI77: 0 | BJ77: 0 | BK77: 0 | BL77: 1 | BM77: 0 | BN77: 0 | BO77: 0 | BP77: 0 | BQ77: 0
A78: ="https://open.spotify.com/playlist/" & C78 | B78: INTENSE Running Music 180–190 BPM 🔥 Fast Songs for Running | High Tempo Jogging Playlist | C78: 3XW1EIKjIdbQV6w5LCCcN1 | D78: 385 | E78: 0 | F78: 3 | G78: 5 | H78: 4 | I78: 8 | J78: 5 | K78: 1 | L78: 1 | M78: 3 | N78: 4 | O78: 1 | P78: 2 | Q78: 1 | R78: 5 | S78: 6 | T78: 8 | U78: 4 | V78: 3 | W78: 2 | X78: 4 | Y78: 7 | Z78: 1 | AA78: 4 | AB78: 2 | AC78: 1 | AD78: 2 | AE78: 4 | AF78: 5 | AG78: 10 | AH78: 6 | AI78: 8 | AJ78: 6 | AK78: 3 | AL78: 7 | AM78: 10 | AN78: 6 | AO78: 5 | AP78: 3 | AQ78: 4 | AR78: 5 | AS78: 4 | AT78: 6 | AU78: 10 | AV78: 6 | AW78: 7 | AX78: 6 | AY78: 4 | AZ78: 8 | BA78: 8 | BB78: 11 | BC78: 7 | BD78: 4 | BE78: 6 | BF78: 9 | BG78: 20 | BH78: 16 | BI78: 19 | BJ78: 11 | BK78: 4 | BL78: 8 | BM78: 4 | BN78: 10 | BO78: 7 | BP78: 4 | BQ78: 6
A79: ="https://open.spotify.com/playlist/" & C79 | B79: ADRENALINE Power Cycling 160 BPM 2026 ⚡ Indoor Spinning Playlist | High-Energy Cardio Music | C79: 4I0azrNdoqeuzx64WhMKvD | D79: 83 | E79: 0 | F79: 0 | G79: 7 | H79: 6 | I79: 2 | J79: 0 | K79: 2 | L79: 2 | M79: 3 | N79: 2 | O79: 1 | P79: 0 | Q79: 0 | R79: 0 | S79: 1 | T79: -1 | U79: 0 | V79: 2 | W79: -1 | X79: 0 | Y79: 4 | Z79: 5 | AB79: 1 | AC79: 2 | AD79: 0 | AE79: 0 | AF79: 4 | AG79: 2 | AH79: 2 | AI79: 1 | AJ79: 3 | AK79: 2 | AL79: 2 | AM79: 1 | AN79: 1 | AO79: 1 | AP79: 0 | AQ79: 0 | AR79: 1 | AS79: 0 | AT79: 2 | AU79: 0 | AV79: 2 | AW79: 0 | AX79: 0 | AY79: 0 | AZ79: 1 | BA79: 1 | BB79: 1 | BC79: 1 | BD79: 1 | BE79: 1 | BF79: 2 | BG79: 0 | BH79: 0 | BI79: -1 | BJ79: 2 | BK79: 1 | BL79: 0 | BM79: 0 | BN79: 1 | BO79: 0 | BP79: 0 | BQ79: 0
A80: ="https://open.spotify.com/playlist/" & C80 | B80: Sacred DRUID Meditation 🌿 | Celtic Forest Ambient & Ritual Atmosphere | C80: 4TNjgx7saNibtwNj8QpIlc | D80: 84 | E80: 0 | F80: 0 | G80: 0 | H80: 0 | I80: 2 | J80: 0 | K80: 0 | L80: 0 | M80: 1 | N80: 3 | O80: 4 | P80: 1 | Q80: 6 | R80: 4 | S80: 2 | T80: 4 | U80: 4 | V80: 5 | W80: 2 | X80: 4 | Y80: 2 | Z80: 1 | AA80: 1 | AB80: 0 | AC80: 2 | AD80: 2 | AE80: 0 | AF80: 1 | AG80: 2 | AH80: 0 | AI80: 1 | AJ80: 0 | AK80: 1 | AL80: 1 | AM80: 1 | AN80: 1 | AO80: 1 | AP80: 2 | AQ80: 1 | AR80: 2 | AS80: 0 | AT80: 0 | AU80: 0 | AV80: 1 | AW80: 0 | AX80: 1 | AY80: 0 | AZ80: 3 | BA80: 0 | BB80: 1 | BC80: 1 | BD80: 0 | BE80: 0 | BF80: 1 | BG80: 0 | BH80: 0 | BI80: 2 | BJ80: 0 | BK80: 1 | BL80: 0 | BM80: 1 | BN80: 0 | BO80: 0 | BP80: 1 | BQ80: 0
A81: ="https://open.spotify.com/playlist/" & C81 | B81: INTENSA Running 180–190 BPM 🔥 Música para Correr Rápido | Playlist Jogging | C81: 0OimUfM688YTJbgTTYIdxi | D81: 713 | E81: 0 | F81: 1 | G81: 0 | H81: 1 | I81: 3 | J81: 1 | K81: 3 | L81: 5 | M81: 2 | N81: 1 | O81: 4 | P81: 7 | Q81: 2 | R81: 10 | S81: 6 | T81: 6 | U81: 5 | V81: 4 | W81: 3 | X81: 5 | Y81: 9 | Z81: 11 | AA81: 3 | AB81: 2 | AC81: 8 | AD81: 9 | AE81: 6 | AF81: 5 | AG81: 11 | AH81: 7 | AI81: 8 | AJ81: 8 | AK81: 21 | AL81: 9 | AM81: 11 | AN81: 17 | AO81: 16 | AP81: 4 | AQ81: 16 | AR81: 5 | AS81: 10 | AT81: 14 | AU81: 15 | AV81: 26 | AW81: 19 | AX81: 17 | AY81: 14 | AZ81: 13 | BA81: 11 | BB81: 26 | BC81: 15 | BD81: 19 | BE81: 22 | BF81: 13 | BG81: 28 | BH81: 23 | BI81: 37 | BJ81: 15 | BK81: 11 | BL81: 17 | BM81: 23 | BN81: 16 | BO81: 14 | BP81: 17 | BQ81: 17
A82: ="https://open.spotify.com/playlist/" & C82 | B82: Running 180 BPM À FOND 🔥 | Musique Rapide pour Sport | Playlist Jogging | C82: 1LziVsQzasZGTaDTeljPuH | D82: 227 | E82: 0 | F82: 2 | G82: 0 | H82: 1 | I82: 1 | J82: 1 | K82: 1 | L82: 5 | M82: 2 | N82: 2 | O82: 2 | P82: 4 | Q82: 4 | R82: 1 | S82: 7 | T82: 5 | U82: 1 | V82: 2 | W82: 2 | X82: 1 | Y82: 1 | Z82: 3 | AA82: 3 | AB82: 5 | AC82: 0 | AD82: 5 | AE82: 1 | AF82: 5 | AG82: 2 | AH82: 4 | AI82: 2 | AJ82: 6 | AK82: 2 | AL82: 1 | AM82: 3 | AN82: 6 | AO82: 5 | AP82: 4 | AQ82: 5 | AR82: 1 | AS82: 3 | AT82: 1 | AU82: 9 | AV82: 10 | AW82: 2 | AX82: 3 | AY82: 1 | AZ82: 4 | BA82: 6 | BB82: 5 | BC82: 1 | BD82: 3 | BE82: 3 | BF82: 5 | BG82: 6 | BH82: 4 | BI82: 7 | BJ82: 6 | BK82: 7 | BL82: 9 | BM82: 4 | BN82: 4 | BO82: 6 | BP82: 5 | BQ82: 1
A83: ="https://open.spotify.com/playlist/" & C83 | B83: Beatport Top 100 | Raw Techno, Deep Techno, Hypnotic Techno Charts 2026 🖤🔊 | C83: 6oGhBUaNe8cZL4Sdte4Qm5 | D83: 112 | E83: 0 | F83: 0 | G83: 2 | H83: 3 | I83: 1 | J83: 2 | K83: 0 | L83: 2 | M83: 3 | N83: 3 | O83: 2 | P83: 1 | Q83: 3 | R83: 2 | S83: 2 | T83: 0 | U83: 2 | V83: 4 | W83: 5 | X83: 1 | Y83: 2 | Z83: 2 | AA83: 1 | AB83: 1 | AC83: 0 | AD83: 1 | AE83: 2 | AF83: 1 | AG83: 1 | AH83: 0 | AI83: 1 | AJ83: 2 | AK83: 4 | AL83: 2 | AM83: -1 | AN83: 1 | AO83: 1 | AP83: 2 | AQ83: 0 | AR83: 1 | AS83: 2 | AT83: 0 | AU83: -1 | AV83: 0 | AW83: 0 | AX83: 0 | AY83: 3 | AZ83: 2 | BA83: -1 | BB83: 1 | BC83: 0 | BD83: -1 | BE83: 1 | BF83: 0 | BG83: 3 | BH83: 0 | BI83: 1 | BJ83: 1 | BK83: 1 | BL83: 2 | BM83: 0 | BN83: 0 | BO83: -1 | BP83: 1 | BQ83: 2
A84: ="https://open.spotify.com/playlist/" & C84 | B84: Dreamy Vibes 2026 | Ethnic House, Melodic Techno, Minimal Techno, Chill Piano 🌙✨ | C84: 0oBc3ihmtnWVBgnfQjgLWr | D84: 25 | E84: 0 | F84: 1 | G84: 1 | H84: 1 | I84: 1 | J84: 0 | K84: 0 | L84: 0 | M84: 2 | N84: 0 | O84: 0 | P84: 0 | Q84: 0 | R84: 0 | S84: 0 | T84: 0 | U84: 1 | V84: 0 | W84: 0 | X84: 0 | Y84: 0 | Z84: 0 | AA84: 0 | AB84: 0 | AC84: 0 | AD84: 0 | AE84: 0 | AF84: 0 | AG84: 0 | AH84: 0 | AI84: 0 | AJ84: 0 | AK84: 0 | AL84: 0 | AM84: 0 | AN84: -1 | AO84: 0 | AP84: 0 | AQ84: 1 | AR84: 0 | AS84: 0 | AT84: 0 | AU84: 1 | AV84: 0 | AW84: 0 | AX84: 1 | AY84: 0 | AZ84: 0 | BA84: 0 | BB84: 0 | BC84: 0 | BD84: 0 | BE84: 0 | BF84: 0 | BG84: 0 | BH84: -1 | BI84: 0 | BJ84: 0 | BK84: 0 | BL84: 0 | BM84: 0 | BN84: 0 | BO84: 0 | BP84: 0 | BQ84: 0
